Workbook

Sheet Cover
B2: Green Corridor Cost Model — Simplified
B4: HOW TO USE
B5: 1. Fill in the blue cells across the Cargo, Vessel, Fuel, Port, and Regulation tabs — each covers one area of the model, mirroring how this will eventually work as a web form. 2. The 'Calculation' tab builds the year-by-year cost and discounts it automatically — no need to edit it. 3. Read the results on the 'Output' tab.
B7: FORMATTING CONVENTION
B8: Blue text = input cell (edit these). Black text = formula (do not overwrite).

Sheet Cargo
B2: Cargo & Corridor
B5: Corridor
B6: Country | D6: Denmark
B7: Corridor type | D7: Point-to-point
B8: Corridor name | D8: Introduce Corridor Name
B9: Port A | D9: Introduce Port A
B10: Port B | D10: Introduce Port B
B11: Corridor length, one-way (nautical miles) | D11: 500
B13: Timeline & economics
B14: Model start year | D14: 2027
B15: Number of years modelled (max 40) | D15: 20
B16: Annual cargo throughput (units/year) | D16: 22167
B17: Discount rate (standard cost of capital) | E17: =IF(D17="",F17,D17) -> 0.055 | F17: =INDEX(Data_tables!$C$25:$C$31,MATCH($D$6,Data_tables!$B$25:$B$31,0)) -> 0.055 | G17: Benchmarked by Country above — override if you have a project-specific WACC
B18: Inflation rate | D18: 0.02

Sheet Vessel
B2: Vessel
B3: Shared vessel choice, plus CAPEX/OPEX for the green and fossil vessel.
B5: Vessel selection (shared by both corridors)
D6: Tanker (35k dwt)
B7: Number of vessels | D7: 1
B8: Roundtrips per year (per vessel) | D8: 12
B9: Green vessel
D11: Your override | E11: Value used | F11: Benchmark
B12: CAPEX ($m, year 1, incl. green fuel-readiness premium) | E12: =IF(D12="",F12,D12) -> 25 | F12: =INDEX(Data_tables!$C$6:$C$11,MATCH($D$6,Data_tables!$B$6:$B$11,0))*(1+INDEX(Data_tables!$K$15:$K$20,MATCH(Fuel!$D$8,Data_tables!$B$15:$B$20,0))) -> 25
B13: OPEX ($m/yr) | E13: =IF(D13="",F13,D13) -> 1.2 | F13: =INDEX(Data_tables!$D$6:$D$11,MATCH($D$6,Data_tables!$B$6:$B$11,0)) -> 1.2
B15: Fossil vessel
D17: Your override | E17: Value used | F17: Benchmark
B18: CAPEX ($m, year 1, baseline, no retrofit) | E18: =IF(D18="",F18,D18) -> 0 | F18: =0 -> 0 | G18: Existing baseline vessel — override if a new-build fossil vessel is being compared
B19: OPEX ($m/yr) | E19: =IF(D19="",F19,D19) -> 1.2 | F19: =INDEX(Data_tables!$D$6:$D$11,MATCH($D$6,Data_tables!$B$6:$B$11,0)) -> 1.2

Sheet Fuel
B2: Fuel
B3: Fuel choice, pricing, emissions, and fuel-production CAPEX/OPEX for each corridor.
B4: Estimate fuel consumption from | D4: Distance (nautical miles)
B6: Green fuel
D8: e-Ammonia
B9: Fuel sourcing: construct plant or purchase fuel? | D9: Construct
D10: Your override | E10: Value used | F10: Benchmark
B11: Fuel price ($/tonne) | E11: =IF(D11="",F11,D11) -> 900 | F11: =INDEX(Data_tables!$C$15:$C$20,MATCH($D$8,Data_tables!$B$15:$B$20,0)) -> 900
B12: CO2 emission factor, combustion (t CO2/t fuel) | E12: =IF(D12="",F12,D12) -> 0.1 | F12: =INDEX(Data_tables!$D$15:$D$20,MATCH($D$8,Data_tables!$B$15:$B$20,0)) -> 0.1
B13: Energy density, LHV (MJ/tonne) | E13: =IF(D13="",F13,D13) -> 18600 | F13: =INDEX(Data_tables!$L$15:$L$20,MATCH($D$8,Data_tables!$B$15:$B$20,0)) -> 18600
B14: GHG intensity, well-to-wake (gCO2eq/MJ) | E14: =IF(D14="",F14,D14) -> 15 | F14: =INDEX(Data_tables!$M$15:$M$20,MATCH($D$8,Data_tables!$B$15:$B$20,0)) -> 15 | G14: Used for FuelEU Maritime compliance — replace with your Proof of Sustainability value
B15: Fuel consumption (tonnes/vessel/year) | E15: =IF(D15="",F15,D15) -> 2580.6452 | F15: =IF($D$4="Distance (nautical miles)",(Cargo!$D$11*2)*Vessel!$D$8*INDEX(Data_tables!$F$6:$F$11,MATCH(Vessel!$D$6,Data_tables!$B$6:$B$11,0))*1000/E13,INDEX(Data_tables!$E$6:$E$11,MATCH(Vessel!$D$6,Data_tables!$B$6:$B$11,0))) -> 2580.6452 | G15: Benchmark based on vessel type, or derived from distance if selected above
B16: Fuel production CAPEX ($m, year 1) | E16: =IF($D$9="Purchase",0,IF(D16="",F16,D16)) -> 55 | F16: =INDEX(Data_tables!$E$15:$E$20,MATCH($D$8,Data_tables!$B$15:$B$20,0)) -> 55 | G16: Forced to 0 if 'Purchase' is selected above
B17: Fuel production O&M, excl. fuel purchase ($m/yr) | E17: =IF($D$9="Purchase",0,IF(D17="",F17,D17)) -> 3 | F17: =INDEX(Data_tables!$F$15:$F$20,MATCH($D$8,Data_tables!$B$15:$B$20,0)) -> 3 | G17: Forced to 0 if 'Purchase' is selected above
B19: Fossil fuel
D21: LSFO (conventional)
B22: Fuel sourcing: construct plant or purchase fuel? | D22: Purchase
D23: Your override | E23: Value used | F23: Benchmark
B24: Fuel price ($/tonne) | E24: =IF(D24="",F24,D24) -> 594 | F24: =INDEX(Data_tables!$C$15:$C$20,MATCH($D$21,Data_tables!$B$15:$B$20,0)) -> 594
B25: CO2 emission factor, combustion (t CO2/t fuel) | E25: =IF(D25="",F25,D25) -> 3.3 | F25: =INDEX(Data_tables!$D$15:$D$20,MATCH($D$21,Data_tables!$B$15:$B$20,0)) -> 3.3
B26: Energy density, LHV (MJ/tonne) | E26: =IF(D26="",F26,D26) -> 40200 | F26: =INDEX(Data_tables!$L$15:$L$20,MATCH($D$21,Data_tables!$B$15:$B$20,0)) -> 40200 | G26: Carried through automatically from fuel type above — override if you have a specific value
B27: GHG intensity, well-to-wake (gCO2eq/MJ) | E27: =IF(D27="",F27,D27) -> 92.4 | F27: =INDEX(Data_tables!$M$15:$M$20,MATCH($D$21,Data_tables!$B$15:$B$20,0)) -> 92.4 | G27: Used for FuelEU Maritime compliance — replace with your Proof of Sustainability value
B28: Fuel consumption (tonnes/vessel/year) | E28: =IF(D28="",F28,D28) -> 1194.0299 | F28: =IF($D$4="Distance (nautical miles)",(Cargo!$D$11*2)*Vessel!$D$8*INDEX(Data_tables!$F$6:$F$11,MATCH(Vessel!$D$6,Data_tables!$B$6:$B$11,0))*1000/E26,INDEX(Data_tables!$E$6:$E$11,MATCH(Vessel!$D$6,Data_tables!$B$6:$B$11,0))) -> 1194.0299 | G28: Same vessel-type/distance benchmark as green — override if the baseline vessel differs
B29: Fuel production CAPEX ($m, year 1) | E29: =IF($D$22="Purchase",0,IF(D29="",F29,D29)) -> 0 | F29: 15 | G29: Forced to 0 if 'Purchase' is selected above (the default)
B30: Fuel production O&M, excl. fuel purchase ($m/yr) | E30: =IF($D$22="Purchase",0,IF(D30="",F30,D30)) -> 0 | F30: 1

Sheet Port
B2: Port
B3: Port storage and port barge CAPEX/OPEX for each corridor.
B5: Green port
D7: Your override | E7: Value used | F7: Benchmark
B8: Port storage — CAPEX ($m, year 1) | E8: =IF(D8="",F8,D8) -> 12 | F8: =INDEX(Data_tables!$G$15:$G$20,MATCH(Fuel!$D$8,Data_tables!$B$15:$B$20,0)) -> 12
B9: Port storage — OPEX ($m/yr) | E9: =IF(D9="",F9,D9) -> 0.5 | F9: =INDEX(Data_tables!$H$15:$H$20,MATCH(Fuel!$D$8,Data_tables!$B$15:$B$20,0)) -> 0.5
B11: Port barge — CAPEX ($m, year 1) | E11: =IF(D11="",F11,D11) -> 5 | F11: =INDEX(Data_tables!$I$15:$I$20,MATCH(Fuel!$D$8,Data_tables!$B$15:$B$20,0)) -> 5
B12: Port barge — OPEX ($m/yr) | E12: =IF(D12="",F12,D12) -> 0.3 | F12: =INDEX(Data_tables!$J$15:$J$20,MATCH(Fuel!$D$8,Data_tables!$B$15:$B$20,0)) -> 0.3
B14: Fossil port
D16: Your override | E16: Value used | F16: Benchmark
B17: Port storage — CAPEX ($m, year 1) | E17: =IF(D17="",F17,D17) -> 0 | F17: =0 -> 0 | G17: Existing infrastructure assumed
B18: Port storage — OPEX ($m/yr) | E18: =IF(D18="",F18,D18) -> 0 | F18: =INDEX(Data_tables!$H$15:$H$20,MATCH(Fuel!$D$21,Data_tables!$B$15:$B$20,0))*0.3 -> 0 | G18: Assumed lower than a new green facility — override with your own figure
B20: Port barge — CAPEX ($m, year 1) | E20: =IF(D20="",F20,D20) -> 0 | F20: =0 -> 0 | G20: Existing infrastructure assumed
B21: Port barge — OPEX ($m/yr) | E21: =IF(D21="",F21,D21) -> 0 | F21: =INDEX(Data_tables!$J$15:$J$20,MATCH(Fuel!$D$21,Data_tables!$B$15:$B$20,0))*0.3 -> 0

Sheet Regulation
B2: Regulation
B3: Applied on top of the corridor costs. Each module can be switched off independently. Figures reflect known 2026 rules/market levels — always confirm current values before relying on results.
B5: 4.1 EU ETS (Emissions Trading System)
B6: Include EU ETS? | D6: Yes
B7: EUA price (€/tonne CO2) | D7: 80
B8: EUR/USD exchange rate | D8: 1.08
B9: % of emissions subject to EU ETS | D9: 1
B11: Phase-in (applied automatically by calendar year): 40% in 2024, 70% in 2025, 100% from 2026
B13: 4.2 FuelEU Maritime
B14: Include FuelEU Maritime? | D14: Yes
B15: Penalty rate (€/tonne VLSFO-equivalent) | D15: 2400
B16: VLSFO energy equivalence (MJ/tonne) | D16: 41000
B17: GHG intensity reference value, 2020 baseline (gCO2eq/MJ) | D17: 91.16
B18: % of energy subject to FuelEU Maritime | D18: 1
B20: Target reduction vs baseline (applied automatically by calendar year):
B21: 2025: -2% 2030: -6% 2035: -14.5% 2040: -31% 2045: -62% 2050: -80%
B23: 4.3 IRA Section 45Z Clean Fuel Production Credit (US)
B24: Include IRA 45Z credit? | D24: No
B25: Is the green fuel produced in the US? | D25: No
B26: Credit rate ($/gallon-equivalent) | D26: 1
B27: Gasoline-gallon-equivalent energy content (MJ/gallon) | D27: 122.5
B29: 4.4 Self-designed regulation
B30: Use this for a country-specific scheme not covered above (e.g. a national carbon price or clean fuel subsidy). All figures assumed to already be in USD.
B31: Include self-designed regulation? | D31: No
B32: CO2 price ($/tonne CO2) | D32: 0
B33: H2-based fuel support ($/kg green fuel) | D33: 0
B34: CAPEX support (% of green CAPEX covered) | D34: 0
B35: OPEX support (% of green OPEX covered) | D35: 0
B36: Other support ($m/year, green corridor) | D36: 0

Sheet Calculation
B2: Calculation
B3: This sheet builds automatically from the Cargo/Vessel/Fuel/Port/Regulation tabs. No need to edit anything here.
B5: Timeline
B7: Year # | D7: 1 | E7: 2 | F7: 3 | G7: 4 | H7: 5 | I7: 6 | J7: 7 | K7: 8 | L7: 9 | M7: 10 | N7: 11 | O7: 12 | P7: 13 | Q7: 14 | R7: 15 | S7: 16 | T7: 17 | U7: 18 | V7: 19 | W7: 20 | X7: 21 | Y7: 22 | Z7: 23 | AA7: 24 | AB7: 25 | AC7: 26 | AD7: 27 | AE7: 28 | AF7: 29 | AG7: 30 | AH7: 31 | AI7: 32 | AJ7: 33 | AK7: 34 | AL7: 35 | AM7: 36 | AN7: 37 | AO7: 38 | AP7: 39 | AQ7: 40
B8: Calendar year | D8: =IF(1<=Cargo!$D$15,Cargo!$D$14+1-1,"") -> 2027 | E8: =IF(2<=Cargo!$D$15,Cargo!$D$14+2-1,"") -> 2028 | F8: =IF(3<=Cargo!$D$15,Cargo!$D$14+3-1,"") -> 2029 | G8: =IF(4<=Cargo!$D$15,Cargo!$D$14+4-1,"") -> 2030 | H8: =IF(5<=Cargo!$D$15,Cargo!$D$14+5-1,"") -> 2031 | I8: =IF(6<=Cargo!$D$15,Cargo!$D$14+6-1,"") -> 2032 | J8: =IF(7<=Cargo!$D$15,Cargo!$D$14+7-1,"") -> 2033 | K8: =IF(8<=Cargo!$D$15,Cargo!$D$14+8-1,"") -> 2034 | L8: =IF(9<=Cargo!$D$15,Cargo!$D$14+9-1,"") -> 2035 | M8: =IF(10<=Cargo!$D$15,Cargo!$D$14+10-1,"") -> 2036 | N8: =IF(11<=Cargo!$D$15,Cargo!$D$14+11-1,"") -> 2037 | O8: =IF(12<=Cargo!$D$15,Cargo!$D$14+12-1,"") -> 2038 | P8: =IF(13<=Cargo!$D$15,Cargo!$D$14+13-1,"") -> 2039 | Q8: =IF(14<=Cargo!$D$15,Cargo!$D$14+14-1,"") -> 2040 | R8: =IF(15<=Cargo!$D$15,Cargo!$D$14+15-1,"") -> 2041 | S8: =IF(16<=Cargo!$D$15,Cargo!$D$14+16-1,"") -> 2042 | T8: =IF(17<=Cargo!$D$15,Cargo!$D$14+17-1,"") -> 2043 | U8: =IF(18<=Cargo!$D$15,Cargo!$D$14+18-1,"") -> 2044 | V8: =IF(19<=Cargo!$D$15,Cargo!$D$14+19-1,"") -> 2045 | W8: =IF(20<=Cargo!$D$15,Cargo!$D$14+20-1,"") -> 2046 | X8: =IF(21<=Cargo!$D$15,Cargo!$D$14+21-1,"") | Y8: =IF(22<=Cargo!$D$15,Cargo!$D$14+22-1,"") | Z8: =IF(23<=Cargo!$D$15,Cargo!$D$14+23-1,"") | AA8: =IF(24<=Cargo!$D$15,Cargo!$D$14+24-1,"") | AB8: =IF(25<=Cargo!$D$15,Cargo!$D$14+25-1,"") | AC8: =IF(26<=Cargo!$D$15,Cargo!$D$14+26-1,"") | AD8: =IF(27<=Cargo!$D$15,Cargo!$D$14+27-1,"") | AE8: =IF(28<=Cargo!$D$15,Cargo!$D$14+28-1,"") | AF8: =IF(29<=Cargo!$D$15,Cargo!$D$14+29-1,"") | AG8: =IF(30<=Cargo!$D$15,Cargo!$D$14+30-1,"") | AH8: =IF(31<=Cargo!$D$15,Cargo!$D$14+31-1,"") | AI8: =IF(32<=Cargo!$D$15,Cargo!$D$14+32-1,"") | AJ8: =IF(33<=Cargo!$D$15,Cargo!$D$14+33-1,"") | AK8: =IF(34<=Cargo!$D$15,Cargo!$D$14+34-1,"") | AL8: =IF(35<=Cargo!$D$15,Cargo!$D$14+35-1,"") | AM8: =IF(36<=Cargo!$D$15,Cargo!$D$14+36-1,"") | AN8: =IF(37<=Cargo!$D$15,Cargo!$D$14+37-1,"") | AO8: =IF(38<=Cargo!$D$15,Cargo!$D$14+38-1,"") | AP8: =IF(39<=Cargo!$D$15,Cargo!$D$14+39-1,"") | AQ8: =IF(40<=Cargo!$D$15,Cargo!$D$14+40-1,"")
B9: Green = year used in the model, red = beyond the modelled horizon.
B11: Green Corridor
B13: Fuel: CAPEX (fuel production, $m) | D13: =IF(1<=Cargo!$D$15,IF(1=1,Fuel!$E$16,0),0) -> 55 | E13: =IF(2<=Cargo!$D$15,IF(2=1,Fuel!$E$16,0),0) -> 0 | F13: =IF(3<=Cargo!$D$15,IF(3=1,Fuel!$E$16,0),0) -> 0 | G13: =IF(4<=Cargo!$D$15,IF(4=1,Fuel!$E$16,0),0) -> 0 | H13: =IF(5<=Cargo!$D$15,IF(5=1,Fuel!$E$16,0),0) -> 0 | I13: =IF(6<=Cargo!$D$15,IF(6=1,Fuel!$E$16,0),0) -> 0 | J13: =IF(7<=Cargo!$D$15,IF(7=1,Fuel!$E$16,0),0) -> 0 | K13: =IF(8<=Cargo!$D$15,IF(8=1,Fuel!$E$16,0),0) -> 0 | L13: =IF(9<=Cargo!$D$15,IF(9=1,Fuel!$E$16,0),0) -> 0 | M13: =IF(10<=Cargo!$D$15,IF(10=1,Fuel!$E$16,0),0) -> 0 | N13: =IF(11<=Cargo!$D$15,IF(11=1,Fuel!$E$16,0),0) -> 0 | O13: =IF(12<=Cargo!$D$15,IF(12=1,Fuel!$E$16,0),0) -> 0 | P13: =IF(13<=Cargo!$D$15,IF(13=1,Fuel!$E$16,0),0) -> 0 | Q13: =IF(14<=Cargo!$D$15,IF(14=1,Fuel!$E$16,0),0) -> 0 | R13: =IF(15<=Cargo!$D$15,IF(15=1,Fuel!$E$16,0),0) -> 0 | S13: =IF(16<=Cargo!$D$15,IF(16=1,Fuel!$E$16,0),0) -> 0 | T13: =IF(17<=Cargo!$D$15,IF(17=1,Fuel!$E$16,0),0) -> 0 | U13: =IF(18<=Cargo!$D$15,IF(18=1,Fuel!$E$16,0),0) -> 0 | V13: =IF(19<=Cargo!$D$15,IF(19=1,Fuel!$E$16,0),0) -> 0 | W13: =IF(20<=Cargo!$D$15,IF(20=1,Fuel!$E$16,0),0) -> 0 | X13: =IF(21<=Cargo!$D$15,IF(21=1,Fuel!$E$16,0),0) -> 0 | Y13: =IF(22<=Cargo!$D$15,IF(22=1,Fuel!$E$16,0),0) -> 0 | Z13: =IF(23<=Cargo!$D$15,IF(23=1,Fuel!$E$16,0),0) -> 0 | AA13: =IF(24<=Cargo!$D$15,IF(24=1,Fuel!$E$16,0),0) -> 0 | AB13: =IF(25<=Cargo!$D$15,IF(25=1,Fuel!$E$16,0),0) -> 0 | AC13: =IF(26<=Cargo!$D$15,IF(26=1,Fuel!$E$16,0),0) -> 0 | AD13: =IF(27<=Cargo!$D$15,IF(27=1,Fuel!$E$16,0),0) -> 0 | AE13: =IF(28<=Cargo!$D$15,IF(28=1,Fuel!$E$16,0),0) -> 0 | AF13: =IF(29<=Cargo!$D$15,IF(29=1,Fuel!$E$16,0),0) -> 0 | AG13: =IF(30<=Cargo!$D$15,IF(30=1,Fuel!$E$16,0),0) -> 0 | AH13: =IF(31<=Cargo!$D$15,IF(31=1,Fuel!$E$16,0),0) -> 0 | AI13: =IF(32<=Cargo!$D$15,IF(32=1,Fuel!$E$16,0),0) -> 0 | AJ13: =IF(33<=Cargo!$D$15,IF(33=1,Fuel!$E$16,0),0) -> 0 | AK13: =IF(34<=Cargo!$D$15,IF(34=1,Fuel!$E$16,0),0) -> 0 | AL13: =IF(35<=Cargo!$D$15,IF(35=1,Fuel!$E$16,0),0) -> 0 | AM13: =IF(36<=Cargo!$D$15,IF(36=1,Fuel!$E$16,0),0) -> 0 | AN13: =IF(37<=Cargo!$D$15,IF(37=1,Fuel!$E$16,0),0) -> 0 | AO13: =IF(38<=Cargo!$D$15,IF(38=1,Fuel!$E$16,0),0) -> 0 | AP13: =IF(39<=Cargo!$D$15,IF(39=1,Fuel!$E$16,0),0) -> 0 | AQ13: =IF(40<=Cargo!$D$15,IF(40=1,Fuel!$E$16,0),0) -> 0
B14: Fuel: OPEX (purchase + O&M, $m) | D14: =IF(1<=Cargo!$D$15,Vessel!$D$7*Fuel!$E$15*Fuel!$E$11/1000000*(1+Cargo!$D$18)^(1-1)+Fuel!$E$17*(1+Cargo!$D$18)^(1-1),0) -> 5.3225806 | E14: =IF(2<=Cargo!$D$15,Vessel!$D$7*Fuel!$E$15*Fuel!$E$11/1000000*(1+Cargo!$D$18)^(2-1)+Fuel!$E$17*(1+Cargo!$D$18)^(2-1),0) -> 5.4290323 | F14: =IF(3<=Cargo!$D$15,Vessel!$D$7*Fuel!$E$15*Fuel!$E$11/1000000*(1+Cargo!$D$18)^(3-1)+Fuel!$E$17*(1+Cargo!$D$18)^(3-1),0) -> 5.5376129 | G14: =IF(4<=Cargo!$D$15,Vessel!$D$7*Fuel!$E$15*Fuel!$E$11/1000000*(1+Cargo!$D$18)^(4-1)+Fuel!$E$17*(1+Cargo!$D$18)^(4-1),0) -> 5.6483652 | H14: =IF(5<=Cargo!$D$15,Vessel!$D$7*Fuel!$E$15*Fuel!$E$11/1000000*(1+Cargo!$D$18)^(5-1)+Fuel!$E$17*(1+Cargo!$D$18)^(5-1),0) -> 5.7613325 | I14: =IF(6<=Cargo!$D$15,Vessel!$D$7*Fuel!$E$15*Fuel!$E$11/1000000*(1+Cargo!$D$18)^(6-1)+Fuel!$E$17*(1+Cargo!$D$18)^(6-1),0) -> 5.8765591 | J14: =IF(7<=Cargo!$D$15,Vessel!$D$7*Fuel!$E$15*Fuel!$E$11/1000000*(1+Cargo!$D$18)^(7-1)+Fuel!$E$17*(1+Cargo!$D$18)^(7-1),0) -> 5.9940903 | K14: =IF(8<=Cargo!$D$15,Vessel!$D$7*Fuel!$E$15*Fuel!$E$11/1000000*(1+Cargo!$D$18)^(8-1)+Fuel!$E$17*(1+Cargo!$D$18)^(8-1),0) -> 6.1139721 | L14: =IF(9<=Cargo!$D$15,Vessel!$D$7*Fuel!$E$15*Fuel!$E$11/1000000*(1+Cargo!$D$18)^(9-1)+Fuel!$E$17*(1+Cargo!$D$18)^(9-1),0) -> 6.2362515 | M14: =IF(10<=Cargo!$D$15,Vessel!$D$7*Fuel!$E$15*Fuel!$E$11/1000000*(1+Cargo!$D$18)^(10-1)+Fuel!$E$17*(1+Cargo!$D$18)^(10-1),0) -> 6.3609766 | N14: =IF(11<=Cargo!$D$15,Vessel!$D$7*Fuel!$E$15*Fuel!$E$11/1000000*(1+Cargo!$D$18)^(11-1)+Fuel!$E$17*(1+Cargo!$D$18)^(11-1),0) -> 6.4881961 | O14: =IF(12<=Cargo!$D$15,Vessel!$D$7*Fuel!$E$15*Fuel!$E$11/1000000*(1+Cargo!$D$18)^(12-1)+Fuel!$E$17*(1+Cargo!$D$18)^(12-1),0) -> 6.61796 | P14: =IF(13<=Cargo!$D$15,Vessel!$D$7*Fuel!$E$15*Fuel!$E$11/1000000*(1+Cargo!$D$18)^(13-1)+Fuel!$E$17*(1+Cargo!$D$18)^(13-1),0) -> 6.7503192 | Q14: =IF(14<=Cargo!$D$15,Vessel!$D$7*Fuel!$E$15*Fuel!$E$11/1000000*(1+Cargo!$D$18)^(14-1)+Fuel!$E$17*(1+Cargo!$D$18)^(14-1),0) -> 6.8853256 | R14: =IF(15<=Cargo!$D$15,Vessel!$D$7*Fuel!$E$15*Fuel!$E$11/1000000*(1+Cargo!$D$18)^(15-1)+Fuel!$E$17*(1+Cargo!$D$18)^(15-1),0) -> 7.0230321 | S14: =IF(16<=Cargo!$D$15,Vessel!$D$7*Fuel!$E$15*Fuel!$E$11/1000000*(1+Cargo!$D$18)^(16-1)+Fuel!$E$17*(1+Cargo!$D$18)^(16-1),0) -> 7.1634928 | T14: =IF(17<=Cargo!$D$15,Vessel!$D$7*Fuel!$E$15*Fuel!$E$11/1000000*(1+Cargo!$D$18)^(17-1)+Fuel!$E$17*(1+Cargo!$D$18)^(17-1),0) -> 7.3067626 | U14: =IF(18<=Cargo!$D$15,Vessel!$D$7*Fuel!$E$15*Fuel!$E$11/1000000*(1+Cargo!$D$18)^(18-1)+Fuel!$E$17*(1+Cargo!$D$18)^(18-1),0) -> 7.4528979 | V14: =IF(19<=Cargo!$D$15,Vessel!$D$7*Fuel!$E$15*Fuel!$E$11/1000000*(1+Cargo!$D$18)^(19-1)+Fuel!$E$17*(1+Cargo!$D$18)^(19-1),0) -> 7.6019558 | W14: =IF(20<=Cargo!$D$15,Vessel!$D$7*Fuel!$E$15*Fuel!$E$11/1000000*(1+Cargo!$D$18)^(20-1)+Fuel!$E$17*(1+Cargo!$D$18)^(20-1),0) -> 7.753995 | X14: =IF(21<=Cargo!$D$15,Vessel!$D$7*Fuel!$E$15*Fuel!$E$11/1000000*(1+Cargo!$D$18)^(21-1)+Fuel!$E$17*(1+Cargo!$D$18)^(21-1),0) -> 0 | Y14: =IF(22<=Cargo!$D$15,Vessel!$D$7*Fuel!$E$15*Fuel!$E$11/1000000*(1+Cargo!$D$18)^(22-1)+Fuel!$E$17*(1+Cargo!$D$18)^(22-1),0) -> 0 | Z14: =IF(23<=Cargo!$D$15,Vessel!$D$7*Fuel!$E$15*Fuel!$E$11/1000000*(1+Cargo!$D$18)^(23-1)+Fuel!$E$17*(1+Cargo!$D$18)^(23-1),0) -> 0 | AA14: =IF(24<=Cargo!$D$15,Vessel!$D$7*Fuel!$E$15*Fuel!$E$11/1000000*(1+Cargo!$D$18)^(24-1)+Fuel!$E$17*(1+Cargo!$D$18)^(24-1),0) -> 0 | AB14: =IF(25<=Cargo!$D$15,Vessel!$D$7*Fuel!$E$15*Fuel!$E$11/1000000*(1+Cargo!$D$18)^(25-1)+Fuel!$E$17*(1+Cargo!$D$18)^(25-1),0) -> 0 | AC14: =IF(26<=Cargo!$D$15,Vessel!$D$7*Fuel!$E$15*Fuel!$E$11/1000000*(1+Cargo!$D$18)^(26-1)+Fuel!$E$17*(1+Cargo!$D$18)^(26-1),0) -> 0 | AD14: =IF(27<=Cargo!$D$15,Vessel!$D$7*Fuel!$E$15*Fuel!$E$11/1000000*(1+Cargo!$D$18)^(27-1)+Fuel!$E$17*(1+Cargo!$D$18)^(27-1),0) -> 0 | AE14: =IF(28<=Cargo!$D$15,Vessel!$D$7*Fuel!$E$15*Fuel!$E$11/1000000*(1+Cargo!$D$18)^(28-1)+Fuel!$E$17*(1+Cargo!$D$18)^(28-1),0) -> 0 | AF14: =IF(29<=Cargo!$D$15,Vessel!$D$7*Fuel!$E$15*Fuel!$E$11/1000000*(1+Cargo!$D$18)^(29-1)+Fuel!$E$17*(1+Cargo!$D$18)^(29-1),0) -> 0 | AG14: =IF(30<=Cargo!$D$15,Vessel!$D$7*Fuel!$E$15*Fuel!$E$11/1000000*(1+Cargo!$D$18)^(30-1)+Fuel!$E$17*(1+Cargo!$D$18)^(30-1),0) -> 0 | AH14: =IF(31<=Cargo!$D$15,Vessel!$D$7*Fuel!$E$15*Fuel!$E$11/1000000*(1+Cargo!$D$18)^(31-1)+Fuel!$E$17*(1+Cargo!$D$18)^(31-1),0) -> 0 | AI14: =IF(32<=Cargo!$D$15,Vessel!$D$7*Fuel!$E$15*Fuel!$E$11/1000000*(1+Cargo!$D$18)^(32-1)+Fuel!$E$17*(1+Cargo!$D$18)^(32-1),0) -> 0 | AJ14: =IF(33<=Cargo!$D$15,Vessel!$D$7*Fuel!$E$15*Fuel!$E$11/1000000*(1+Cargo!$D$18)^(33-1)+Fuel!$E$17*(1+Cargo!$D$18)^(33-1),0) -> 0 | AK14: =IF(34<=Cargo!$D$15,Vessel!$D$7*Fuel!$E$15*Fuel!$E$11/1000000*(1+Cargo!$D$18)^(34-1)+Fuel!$E$17*(1+Cargo!$D$18)^(34-1),0) -> 0 | AL14: =IF(35<=Cargo!$D$15,Vessel!$D$7*Fuel!$E$15*Fuel!$E$11/1000000*(1+Cargo!$D$18)^(35-1)+Fuel!$E$17*(1+Cargo!$D$18)^(35-1),0) -> 0 | AM14: =IF(36<=Cargo!$D$15,Vessel!$D$7*Fuel!$E$15*Fuel!$E$11/1000000*(1+Cargo!$D$18)^(36-1)+Fuel!$E$17*(1+Cargo!$D$18)^(36-1),0) -> 0 | AN14: =IF(37<=Cargo!$D$15,Vessel!$D$7*Fuel!$E$15*Fuel!$E$11/1000000*(1+Cargo!$D$18)^(37-1)+Fuel!$E$17*(1+Cargo!$D$18)^(37-1),0) -> 0 | AO14: =IF(38<=Cargo!$D$15,Vessel!$D$7*Fuel!$E$15*Fuel!$E$11/1000000*(1+Cargo!$D$18)^(38-1)+Fuel!$E$17*(1+Cargo!$D$18)^(38-1),0) -> 0 | AP14: =IF(39<=Cargo!$D$15,Vessel!$D$7*Fuel!$E$15*Fuel!$E$11/1000000*(1+Cargo!$D$18)^(39-1)+Fuel!$E$17*(1+Cargo!$D$18)^(39-1),0) -> 0 | AQ14: =IF(40<=Cargo!$D$15,Vessel!$D$7*Fuel!$E$15*Fuel!$E$11/1000000*(1+Cargo!$D$18)^(40-1)+Fuel!$E$17*(1+Cargo!$D$18)^(40-1),0) -> 0
B16: Port storage: CAPEX ($m) | D16: =IF(1<=Cargo!$D$15,IF(1=1,Port!$E$8,0),0) -> 12 | E16: =IF(2<=Cargo!$D$15,IF(2=1,Port!$E$8,0),0) -> 0 | F16: =IF(3<=Cargo!$D$15,IF(3=1,Port!$E$8,0),0) -> 0 | G16: =IF(4<=Cargo!$D$15,IF(4=1,Port!$E$8,0),0) -> 0 | H16: =IF(5<=Cargo!$D$15,IF(5=1,Port!$E$8,0),0) -> 0 | I16: =IF(6<=Cargo!$D$15,IF(6=1,Port!$E$8,0),0) -> 0 | J16: =IF(7<=Cargo!$D$15,IF(7=1,Port!$E$8,0),0) -> 0 | K16: =IF(8<=Cargo!$D$15,IF(8=1,Port!$E$8,0),0) -> 0 | L16: =IF(9<=Cargo!$D$15,IF(9=1,Port!$E$8,0),0) -> 0 | M16: =IF(10<=Cargo!$D$15,IF(10=1,Port!$E$8,0),0) -> 0 | N16: =IF(11<=Cargo!$D$15,IF(11=1,Port!$E$8,0),0) -> 0 | O16: =IF(12<=Cargo!$D$15,IF(12=1,Port!$E$8,0),0) -> 0 | P16: =IF(13<=Cargo!$D$15,IF(13=1,Port!$E$8,0),0) -> 0 | Q16: =IF(14<=Cargo!$D$15,IF(14=1,Port!$E$8,0),0) -> 0 | R16: =IF(15<=Cargo!$D$15,IF(15=1,Port!$E$8,0),0) -> 0 | S16: =IF(16<=Cargo!$D$15,IF(16=1,Port!$E$8,0),0) -> 0 | T16: =IF(17<=Cargo!$D$15,IF(17=1,Port!$E$8,0),0) -> 0 | U16: =IF(18<=Cargo!$D$15,IF(18=1,Port!$E$8,0),0) -> 0 | V16: =IF(19<=Cargo!$D$15,IF(19=1,Port!$E$8,0),0) -> 0 | W16: =IF(20<=Cargo!$D$15,IF(20=1,Port!$E$8,0),0) -> 0 | X16: =IF(21<=Cargo!$D$15,IF(21=1,Port!$E$8,0),0) -> 0 | Y16: =IF(22<=Cargo!$D$15,IF(22=1,Port!$E$8,0),0) -> 0 | Z16: =IF(23<=Cargo!$D$15,IF(23=1,Port!$E$8,0),0) -> 0 | AA16: =IF(24<=Cargo!$D$15,IF(24=1,Port!$E$8,0),0) -> 0 | AB16: =IF(25<=Cargo!$D$15,IF(25=1,Port!$E$8,0),0) -> 0 | AC16: =IF(26<=Cargo!$D$15,IF(26=1,Port!$E$8,0),0) -> 0 | AD16: =IF(27<=Cargo!$D$15,IF(27=1,Port!$E$8,0),0) -> 0 | AE16: =IF(28<=Cargo!$D$15,IF(28=1,Port!$E$8,0),0) -> 0 | AF16: =IF(29<=Cargo!$D$15,IF(29=1,Port!$E$8,0),0) -> 0 | AG16: =IF(30<=Cargo!$D$15,IF(30=1,Port!$E$8,0),0) -> 0 | AH16: =IF(31<=Cargo!$D$15,IF(31=1,Port!$E$8,0),0) -> 0 | AI16: =IF(32<=Cargo!$D$15,IF(32=1,Port!$E$8,0),0) -> 0 | AJ16: =IF(33<=Cargo!$D$15,IF(33=1,Port!$E$8,0),0) -> 0 | AK16: =IF(34<=Cargo!$D$15,IF(34=1,Port!$E$8,0),0) -> 0 | AL16: =IF(35<=Cargo!$D$15,IF(35=1,Port!$E$8,0),0) -> 0 | AM16: =IF(36<=Cargo!$D$15,IF(36=1,Port!$E$8,0),0) -> 0 | AN16: =IF(37<=Cargo!$D$15,IF(37=1,Port!$E$8,0),0) -> 0 | AO16: =IF(38<=Cargo!$D$15,IF(38=1,Port!$E$8,0),0) -> 0 | AP16: =IF(39<=Cargo!$D$15,IF(39=1,Port!$E$8,0),0) -> 0 | AQ16: =IF(40<=Cargo!$D$15,IF(40=1,Port!$E$8,0),0) -> 0
B17: Port storage: OPEX ($m) | D17: =IF(1<=Cargo!$D$15,Port!$E$9*(1+Cargo!$D$18)^(1-1),0) -> 0.5 | E17: =IF(2<=Cargo!$D$15,Port!$E$9*(1+Cargo!$D$18)^(2-1),0) -> 0.51 | F17: =IF(3<=Cargo!$D$15,Port!$E$9*(1+Cargo!$D$18)^(3-1),0) -> 0.5202 | G17: =IF(4<=Cargo!$D$15,Port!$E$9*(1+Cargo!$D$18)^(4-1),0) -> 0.530604 | H17: =IF(5<=Cargo!$D$15,Port!$E$9*(1+Cargo!$D$18)^(5-1),0) -> 0.54121608 | I17: =IF(6<=Cargo!$D$15,Port!$E$9*(1+Cargo!$D$18)^(6-1),0) -> 0.5520404 | J17: =IF(7<=Cargo!$D$15,Port!$E$9*(1+Cargo!$D$18)^(7-1),0) -> 0.56308121 | K17: =IF(8<=Cargo!$D$15,Port!$E$9*(1+Cargo!$D$18)^(8-1),0) -> 0.57434283 | L17: =IF(9<=Cargo!$D$15,Port!$E$9*(1+Cargo!$D$18)^(9-1),0) -> 0.58582969 | M17: =IF(10<=Cargo!$D$15,Port!$E$9*(1+Cargo!$D$18)^(10-1),0) -> 0.59754628 | N17: =IF(11<=Cargo!$D$15,Port!$E$9*(1+Cargo!$D$18)^(11-1),0) -> 0.60949721 | O17: =IF(12<=Cargo!$D$15,Port!$E$9*(1+Cargo!$D$18)^(12-1),0) -> 0.62168715 | P17: =IF(13<=Cargo!$D$15,Port!$E$9*(1+Cargo!$D$18)^(13-1),0) -> 0.6341209 | Q17: =IF(14<=Cargo!$D$15,Port!$E$9*(1+Cargo!$D$18)^(14-1),0) -> 0.64680332 | R17: =IF(15<=Cargo!$D$15,Port!$E$9*(1+Cargo!$D$18)^(15-1),0) -> 0.65973938 | S17: =IF(16<=Cargo!$D$15,Port!$E$9*(1+Cargo!$D$18)^(16-1),0) -> 0.67293417 | T17: =IF(17<=Cargo!$D$15,Port!$E$9*(1+Cargo!$D$18)^(17-1),0) -> 0.68639285 | U17: =IF(18<=Cargo!$D$15,Port!$E$9*(1+Cargo!$D$18)^(18-1),0) -> 0.70012071 | V17: =IF(19<=Cargo!$D$15,Port!$E$9*(1+Cargo!$D$18)^(19-1),0) -> 0.71412312 | W17: =IF(20<=Cargo!$D$15,Port!$E$9*(1+Cargo!$D$18)^(20-1),0) -> 0.72840559 | X17: =IF(21<=Cargo!$D$15,Port!$E$9*(1+Cargo!$D$18)^(21-1),0) -> 0 | Y17: =IF(22<=Cargo!$D$15,Port!$E$9*(1+Cargo!$D$18)^(22-1),0) -> 0 | Z17: =IF(23<=Cargo!$D$15,Port!$E$9*(1+Cargo!$D$18)^(23-1),0) -> 0 | AA17: =IF(24<=Cargo!$D$15,Port!$E$9*(1+Cargo!$D$18)^(24-1),0) -> 0 | AB17: =IF(25<=Cargo!$D$15,Port!$E$9*(1+Cargo!$D$18)^(25-1),0) -> 0 | AC17: =IF(26<=Cargo!$D$15,Port!$E$9*(1+Cargo!$D$18)^(26-1),0) -> 0 | AD17: =IF(27<=Cargo!$D$15,Port!$E$9*(1+Cargo!$D$18)^(27-1),0) -> 0 | AE17: =IF(28<=Cargo!$D$15,Port!$E$9*(1+Cargo!$D$18)^(28-1),0) -> 0 | AF17: =IF(29<=Cargo!$D$15,Port!$E$9*(1+Cargo!$D$18)^(29-1),0) -> 0 | AG17: =IF(30<=Cargo!$D$15,Port!$E$9*(1+Cargo!$D$18)^(30-1),0) -> 0 | AH17: =IF(31<=Cargo!$D$15,Port!$E$9*(1+Cargo!$D$18)^(31-1),0) -> 0 | AI17: =IF(32<=Cargo!$D$15,Port!$E$9*(1+Cargo!$D$18)^(32-1),0) -> 0 | AJ17: =IF(33<=Cargo!$D$15,Port!$E$9*(1+Cargo!$D$18)^(33-1),0) -> 0 | AK17: =IF(34<=Cargo!$D$15,Port!$E$9*(1+Cargo!$D$18)^(34-1),0) -> 0 | AL17: =IF(35<=Cargo!$D$15,Port!$E$9*(1+Cargo!$D$18)^(35-1),0) -> 0 | AM17: =IF(36<=Cargo!$D$15,Port!$E$9*(1+Cargo!$D$18)^(36-1),0) -> 0 | AN17: =IF(37<=Cargo!$D$15,Port!$E$9*(1+Cargo!$D$18)^(37-1),0) -> 0 | AO17: =IF(38<=Cargo!$D$15,Port!$E$9*(1+Cargo!$D$18)^(38-1),0) -> 0 | AP17: =IF(39<=Cargo!$D$15,Port!$E$9*(1+Cargo!$D$18)^(39-1),0) -> 0 | AQ17: =IF(40<=Cargo!$D$15,Port!$E$9*(1+Cargo!$D$18)^(40-1),0) -> 0
B19: Port barge: CAPEX ($m) | D19: =IF(1<=Cargo!$D$15,IF(1=1,Port!$E$11,0),0) -> 5 | E19: =IF(2<=Cargo!$D$15,IF(2=1,Port!$E$11,0),0) -> 0 | F19: =IF(3<=Cargo!$D$15,IF(3=1,Port!$E$11,0),0) -> 0 | G19: =IF(4<=Cargo!$D$15,IF(4=1,Port!$E$11,0),0) -> 0 | H19: =IF(5<=Cargo!$D$15,IF(5=1,Port!$E$11,0),0) -> 0 | I19: =IF(6<=Cargo!$D$15,IF(6=1,Port!$E$11,0),0) -> 0 | J19: =IF(7<=Cargo!$D$15,IF(7=1,Port!$E$11,0),0) -> 0 | K19: =IF(8<=Cargo!$D$15,IF(8=1,Port!$E$11,0),0) -> 0 | L19: =IF(9<=Cargo!$D$15,IF(9=1,Port!$E$11,0),0) -> 0 | M19: =IF(10<=Cargo!$D$15,IF(10=1,Port!$E$11,0),0) -> 0 | N19: =IF(11<=Cargo!$D$15,IF(11=1,Port!$E$11,0),0) -> 0 | O19: =IF(12<=Cargo!$D$15,IF(12=1,Port!$E$11,0),0) -> 0 | P19: =IF(13<=Cargo!$D$15,IF(13=1,Port!$E$11,0),0) -> 0 | Q19: =IF(14<=Cargo!$D$15,IF(14=1,Port!$E$11,0),0) -> 0 | R19: =IF(15<=Cargo!$D$15,IF(15=1,Port!$E$11,0),0) -> 0 | S19: =IF(16<=Cargo!$D$15,IF(16=1,Port!$E$11,0),0) -> 0 | T19: =IF(17<=Cargo!$D$15,IF(17=1,Port!$E$11,0),0) -> 0 | U19: =IF(18<=Cargo!$D$15,IF(18=1,Port!$E$11,0),0) -> 0 | V19: =IF(19<=Cargo!$D$15,IF(19=1,Port!$E$11,0),0) -> 0 | W19: =IF(20<=Cargo!$D$15,IF(20=1,Port!$E$11,0),0) -> 0 | X19: =IF(21<=Cargo!$D$15,IF(21=1,Port!$E$11,0),0) -> 0 | Y19: =IF(22<=Cargo!$D$15,IF(22=1,Port!$E$11,0),0) -> 0 | Z19: =IF(23<=Cargo!$D$15,IF(23=1,Port!$E$11,0),0) -> 0 | AA19: =IF(24<=Cargo!$D$15,IF(24=1,Port!$E$11,0),0) -> 0 | AB19: =IF(25<=Cargo!$D$15,IF(25=1,Port!$E$11,0),0) -> 0 | AC19: =IF(26<=Cargo!$D$15,IF(26=1,Port!$E$11,0),0) -> 0 | AD19: =IF(27<=Cargo!$D$15,IF(27=1,Port!$E$11,0),0) -> 0 | AE19: =IF(28<=Cargo!$D$15,IF(28=1,Port!$E$11,0),0) -> 0 | AF19: =IF(29<=Cargo!$D$15,IF(29=1,Port!$E$11,0),0) -> 0 | AG19: =IF(30<=Cargo!$D$15,IF(30=1,Port!$E$11,0),0) -> 0 | AH19: =IF(31<=Cargo!$D$15,IF(31=1,Port!$E$11,0),0) -> 0 | AI19: =IF(32<=Cargo!$D$15,IF(32=1,Port!$E$11,0),0) -> 0 | AJ19: =IF(33<=Cargo!$D$15,IF(33=1,Port!$E$11,0),0) -> 0 | AK19: =IF(34<=Cargo!$D$15,IF(34=1,Port!$E$11,0),0) -> 0 | AL19: =IF(35<=Cargo!$D$15,IF(35=1,Port!$E$11,0),0) -> 0 | AM19: =IF(36<=Cargo!$D$15,IF(36=1,Port!$E$11,0),0) -> 0 | AN19: =IF(37<=Cargo!$D$15,IF(37=1,Port!$E$11,0),0) -> 0 | AO19: =IF(38<=Cargo!$D$15,IF(38=1,Port!$E$11,0),0) -> 0 | AP19: =IF(39<=Cargo!$D$15,IF(39=1,Port!$E$11,0),0) -> 0 | AQ19: =IF(40<=Cargo!$D$15,IF(40=1,Port!$E$11,0),0) -> 0
B20: Port barge: OPEX ($m) | D20: =IF(1<=Cargo!$D$15,Port!$E$12*(1+Cargo!$D$18)^(1-1),0) -> 0.3 | E20: =IF(2<=Cargo!$D$15,Port!$E$12*(1+Cargo!$D$18)^(2-1),0) -> 0.306 | F20: =IF(3<=Cargo!$D$15,Port!$E$12*(1+Cargo!$D$18)^(3-1),0) -> 0.31212 | G20: =IF(4<=Cargo!$D$15,Port!$E$12*(1+Cargo!$D$18)^(4-1),0) -> 0.3183624 | H20: =IF(5<=Cargo!$D$15,Port!$E$12*(1+Cargo!$D$18)^(5-1),0) -> 0.32472965 | I20: =IF(6<=Cargo!$D$15,Port!$E$12*(1+Cargo!$D$18)^(6-1),0) -> 0.33122424 | J20: =IF(7<=Cargo!$D$15,Port!$E$12*(1+Cargo!$D$18)^(7-1),0) -> 0.33784873 | K20: =IF(8<=Cargo!$D$15,Port!$E$12*(1+Cargo!$D$18)^(8-1),0) -> 0.3446057 | L20: =IF(9<=Cargo!$D$15,Port!$E$12*(1+Cargo!$D$18)^(9-1),0) -> 0.35149781 | M20: =IF(10<=Cargo!$D$15,Port!$E$12*(1+Cargo!$D$18)^(10-1),0) -> 0.35852777 | N20: =IF(11<=Cargo!$D$15,Port!$E$12*(1+Cargo!$D$18)^(11-1),0) -> 0.36569833 | O20: =IF(12<=Cargo!$D$15,Port!$E$12*(1+Cargo!$D$18)^(12-1),0) -> 0.37301229 | P20: =IF(13<=Cargo!$D$15,Port!$E$12*(1+Cargo!$D$18)^(13-1),0) -> 0.38047254 | Q20: =IF(14<=Cargo!$D$15,Port!$E$12*(1+Cargo!$D$18)^(14-1),0) -> 0.38808199 | R20: =IF(15<=Cargo!$D$15,Port!$E$12*(1+Cargo!$D$18)^(15-1),0) -> 0.39584363 | S20: =IF(16<=Cargo!$D$15,Port!$E$12*(1+Cargo!$D$18)^(16-1),0) -> 0.4037605 | T20: =IF(17<=Cargo!$D$15,Port!$E$12*(1+Cargo!$D$18)^(17-1),0) -> 0.41183571 | U20: =IF(18<=Cargo!$D$15,Port!$E$12*(1+Cargo!$D$18)^(18-1),0) -> 0.42007243 | V20: =IF(19<=Cargo!$D$15,Port!$E$12*(1+Cargo!$D$18)^(19-1),0) -> 0.42847387 | W20: =IF(20<=Cargo!$D$15,Port!$E$12*(1+Cargo!$D$18)^(20-1),0) -> 0.43704335 | X20: =IF(21<=Cargo!$D$15,Port!$E$12*(1+Cargo!$D$18)^(21-1),0) -> 0 | Y20: =IF(22<=Cargo!$D$15,Port!$E$12*(1+Cargo!$D$18)^(22-1),0) -> 0 | Z20: =IF(23<=Cargo!$D$15,Port!$E$12*(1+Cargo!$D$18)^(23-1),0) -> 0 | AA20: =IF(24<=Cargo!$D$15,Port!$E$12*(1+Cargo!$D$18)^(24-1),0) -> 0 | AB20: =IF(25<=Cargo!$D$15,Port!$E$12*(1+Cargo!$D$18)^(25-1),0) -> 0 | AC20: =IF(26<=Cargo!$D$15,Port!$E$12*(1+Cargo!$D$18)^(26-1),0) -> 0 | AD20: =IF(27<=Cargo!$D$15,Port!$E$12*(1+Cargo!$D$18)^(27-1),0) -> 0 | AE20: =IF(28<=Cargo!$D$15,Port!$E$12*(1+Cargo!$D$18)^(28-1),0) -> 0 | AF20: =IF(29<=Cargo!$D$15,Port!$E$12*(1+Cargo!$D$18)^(29-1),0) -> 0 | AG20: =IF(30<=Cargo!$D$15,Port!$E$12*(1+Cargo!$D$18)^(30-1),0) -> 0 | AH20: =IF(31<=Cargo!$D$15,Port!$E$12*(1+Cargo!$D$18)^(31-1),0) -> 0 | AI20: =IF(32<=Cargo!$D$15,Port!$E$12*(1+Cargo!$D$18)^(32-1),0) -> 0 | AJ20: =IF(33<=Cargo!$D$15,Port!$E$12*(1+Cargo!$D$18)^(33-1),0) -> 0 | AK20: =IF(34<=Cargo!$D$15,Port!$E$12*(1+Cargo!$D$18)^(34-1),0) -> 0 | AL20: =IF(35<=Cargo!$D$15,Port!$E$12*(1+Cargo!$D$18)^(35-1),0) -> 0 | AM20: =IF(36<=Cargo!$D$15,Port!$E$12*(1+Cargo!$D$18)^(36-1),0) -> 0 | AN20: =IF(37<=Cargo!$D$15,Port!$E$12*(1+Cargo!$D$18)^(37-1),0) -> 0 | AO20: =IF(38<=Cargo!$D$15,Port!$E$12*(1+Cargo!$D$18)^(38-1),0) -> 0 | AP20: =IF(39<=Cargo!$D$15,Port!$E$12*(1+Cargo!$D$18)^(39-1),0) -> 0 | AQ20: =IF(40<=Cargo!$D$15,Port!$E$12*(1+Cargo!$D$18)^(40-1),0) -> 0
B22: Vessel: CAPEX ($m) | D22: =IF(1<=Cargo!$D$15,IF(1=1,Vessel!$E$12,0),0) -> 25 | E22: =IF(2<=Cargo!$D$15,IF(2=1,Vessel!$E$12,0),0) -> 0 | F22: =IF(3<=Cargo!$D$15,IF(3=1,Vessel!$E$12,0),0) -> 0 | G22: =IF(4<=Cargo!$D$15,IF(4=1,Vessel!$E$12,0),0) -> 0 | H22: =IF(5<=Cargo!$D$15,IF(5=1,Vessel!$E$12,0),0) -> 0 | I22: =IF(6<=Cargo!$D$15,IF(6=1,Vessel!$E$12,0),0) -> 0 | J22: =IF(7<=Cargo!$D$15,IF(7=1,Vessel!$E$12,0),0) -> 0 | K22: =IF(8<=Cargo!$D$15,IF(8=1,Vessel!$E$12,0),0) -> 0 | L22: =IF(9<=Cargo!$D$15,IF(9=1,Vessel!$E$12,0),0) -> 0 | M22: =IF(10<=Cargo!$D$15,IF(10=1,Vessel!$E$12,0),0) -> 0 | N22: =IF(11<=Cargo!$D$15,IF(11=1,Vessel!$E$12,0),0) -> 0 | O22: =IF(12<=Cargo!$D$15,IF(12=1,Vessel!$E$12,0),0) -> 0 | P22: =IF(13<=Cargo!$D$15,IF(13=1,Vessel!$E$12,0),0) -> 0 | Q22: =IF(14<=Cargo!$D$15,IF(14=1,Vessel!$E$12,0),0) -> 0 | R22: =IF(15<=Cargo!$D$15,IF(15=1,Vessel!$E$12,0),0) -> 0 | S22: =IF(16<=Cargo!$D$15,IF(16=1,Vessel!$E$12,0),0) -> 0 | T22: =IF(17<=Cargo!$D$15,IF(17=1,Vessel!$E$12,0),0) -> 0 | U22: =IF(18<=Cargo!$D$15,IF(18=1,Vessel!$E$12,0),0) -> 0 | V22: =IF(19<=Cargo!$D$15,IF(19=1,Vessel!$E$12,0),0) -> 0 | W22: =IF(20<=Cargo!$D$15,IF(20=1,Vessel!$E$12,0),0) -> 0 | X22: =IF(21<=Cargo!$D$15,IF(21=1,Vessel!$E$12,0),0) -> 0 | Y22: =IF(22<=Cargo!$D$15,IF(22=1,Vessel!$E$12,0),0) -> 0 | Z22: =IF(23<=Cargo!$D$15,IF(23=1,Vessel!$E$12,0),0) -> 0 | AA22: =IF(24<=Cargo!$D$15,IF(24=1,Vessel!$E$12,0),0) -> 0 | AB22: =IF(25<=Cargo!$D$15,IF(25=1,Vessel!$E$12,0),0) -> 0 | AC22: =IF(26<=Cargo!$D$15,IF(26=1,Vessel!$E$12,0),0) -> 0 | AD22: =IF(27<=Cargo!$D$15,IF(27=1,Vessel!$E$12,0),0) -> 0 | AE22: =IF(28<=Cargo!$D$15,IF(28=1,Vessel!$E$12,0),0) -> 0 | AF22: =IF(29<=Cargo!$D$15,IF(29=1,Vessel!$E$12,0),0) -> 0 | AG22: =IF(30<=Cargo!$D$15,IF(30=1,Vessel!$E$12,0),0) -> 0 | AH22: =IF(31<=Cargo!$D$15,IF(31=1,Vessel!$E$12,0),0) -> 0 | AI22: =IF(32<=Cargo!$D$15,IF(32=1,Vessel!$E$12,0),0) -> 0 | AJ22: =IF(33<=Cargo!$D$15,IF(33=1,Vessel!$E$12,0),0) -> 0 | AK22: =IF(34<=Cargo!$D$15,IF(34=1,Vessel!$E$12,0),0) -> 0 | AL22: =IF(35<=Cargo!$D$15,IF(35=1,Vessel!$E$12,0),0) -> 0 | AM22: =IF(36<=Cargo!$D$15,IF(36=1,Vessel!$E$12,0),0) -> 0 | AN22: =IF(37<=Cargo!$D$15,IF(37=1,Vessel!$E$12,0),0) -> 0 | AO22: =IF(38<=Cargo!$D$15,IF(38=1,Vessel!$E$12,0),0) -> 0 | AP22: =IF(39<=Cargo!$D$15,IF(39=1,Vessel!$E$12,0),0) -> 0 | AQ22: =IF(40<=Cargo!$D$15,IF(40=1,Vessel!$E$12,0),0) -> 0
B23: Vessel: OPEX ($m) | D23: =IF(1<=Cargo!$D$15,Vessel!$E$13*(1+Cargo!$D$18)^(1-1),0) -> 1.2 | E23: =IF(2<=Cargo!$D$15,Vessel!$E$13*(1+Cargo!$D$18)^(2-1),0) -> 1.224 | F23: =IF(3<=Cargo!$D$15,Vessel!$E$13*(1+Cargo!$D$18)^(3-1),0) -> 1.24848 | G23: =IF(4<=Cargo!$D$15,Vessel!$E$13*(1+Cargo!$D$18)^(4-1),0) -> 1.2734496 | H23: =IF(5<=Cargo!$D$15,Vessel!$E$13*(1+Cargo!$D$18)^(5-1),0) -> 1.2989186 | I23: =IF(6<=Cargo!$D$15,Vessel!$E$13*(1+Cargo!$D$18)^(6-1),0) -> 1.324897 | J23: =IF(7<=Cargo!$D$15,Vessel!$E$13*(1+Cargo!$D$18)^(7-1),0) -> 1.3513949 | K23: =IF(8<=Cargo!$D$15,Vessel!$E$13*(1+Cargo!$D$18)^(8-1),0) -> 1.3784228 | L23: =IF(9<=Cargo!$D$15,Vessel!$E$13*(1+Cargo!$D$18)^(9-1),0) -> 1.4059913 | M23: =IF(10<=Cargo!$D$15,Vessel!$E$13*(1+Cargo!$D$18)^(10-1),0) -> 1.4341111 | N23: =IF(11<=Cargo!$D$15,Vessel!$E$13*(1+Cargo!$D$18)^(11-1),0) -> 1.4627933 | O23: =IF(12<=Cargo!$D$15,Vessel!$E$13*(1+Cargo!$D$18)^(12-1),0) -> 1.4920492 | P23: =IF(13<=Cargo!$D$15,Vessel!$E$13*(1+Cargo!$D$18)^(13-1),0) -> 1.5218902 | Q23: =IF(14<=Cargo!$D$15,Vessel!$E$13*(1+Cargo!$D$18)^(14-1),0) -> 1.552328 | R23: =IF(15<=Cargo!$D$15,Vessel!$E$13*(1+Cargo!$D$18)^(15-1),0) -> 1.5833745 | S23: =IF(16<=Cargo!$D$15,Vessel!$E$13*(1+Cargo!$D$18)^(16-1),0) -> 1.615042 | T23: =IF(17<=Cargo!$D$15,Vessel!$E$13*(1+Cargo!$D$18)^(17-1),0) -> 1.6473428 | U23: =IF(18<=Cargo!$D$15,Vessel!$E$13*(1+Cargo!$D$18)^(18-1),0) -> 1.6802897 | V23: =IF(19<=Cargo!$D$15,Vessel!$E$13*(1+Cargo!$D$18)^(19-1),0) -> 1.7138955 | W23: =IF(20<=Cargo!$D$15,Vessel!$E$13*(1+Cargo!$D$18)^(20-1),0) -> 1.7481734 | X23: =IF(21<=Cargo!$D$15,Vessel!$E$13*(1+Cargo!$D$18)^(21-1),0) -> 0 | Y23: =IF(22<=Cargo!$D$15,Vessel!$E$13*(1+Cargo!$D$18)^(22-1),0) -> 0 | Z23: =IF(23<=Cargo!$D$15,Vessel!$E$13*(1+Cargo!$D$18)^(23-1),0) -> 0 | AA23: =IF(24<=Cargo!$D$15,Vessel!$E$13*(1+Cargo!$D$18)^(24-1),0) -> 0 | AB23: =IF(25<=Cargo!$D$15,Vessel!$E$13*(1+Cargo!$D$18)^(25-1),0) -> 0 | AC23: =IF(26<=Cargo!$D$15,Vessel!$E$13*(1+Cargo!$D$18)^(26-1),0) -> 0 | AD23: =IF(27<=Cargo!$D$15,Vessel!$E$13*(1+Cargo!$D$18)^(27-1),0) -> 0 | AE23: =IF(28<=Cargo!$D$15,Vessel!$E$13*(1+Cargo!$D$18)^(28-1),0) -> 0 | AF23: =IF(29<=Cargo!$D$15,Vessel!$E$13*(1+Cargo!$D$18)^(29-1),0) -> 0 | AG23: =IF(30<=Cargo!$D$15,Vessel!$E$13*(1+Cargo!$D$18)^(30-1),0) -> 0 | AH23: =IF(31<=Cargo!$D$15,Vessel!$E$13*(1+Cargo!$D$18)^(31-1),0) -> 0 | AI23: =IF(32<=Cargo!$D$15,Vessel!$E$13*(1+Cargo!$D$18)^(32-1),0) -> 0 | AJ23: =IF(33<=Cargo!$D$15,Vessel!$E$13*(1+Cargo!$D$18)^(33-1),0) -> 0 | AK23: =IF(34<=Cargo!$D$15,Vessel!$E$13*(1+Cargo!$D$18)^(34-1),0) -> 0 | AL23: =IF(35<=Cargo!$D$15,Vessel!$E$13*(1+Cargo!$D$18)^(35-1),0) -> 0 | AM23: =IF(36<=Cargo!$D$15,Vessel!$E$13*(1+Cargo!$D$18)^(36-1),0) -> 0 | AN23: =IF(37<=Cargo!$D$15,Vessel!$E$13*(1+Cargo!$D$18)^(37-1),0) -> 0 | AO23: =IF(38<=Cargo!$D$15,Vessel!$E$13*(1+Cargo!$D$18)^(38-1),0) -> 0 | AP23: =IF(39<=Cargo!$D$15,Vessel!$E$13*(1+Cargo!$D$18)^(39-1),0) -> 0 | AQ23: =IF(40<=Cargo!$D$15,Vessel!$E$13*(1+Cargo!$D$18)^(40-1),0) -> 0
B25: Total CAPEX ($m) | D25: =+D13+D16+D19+D22 -> 97 | E25: =+E13+E16+E19+E22 -> 0 | F25: =+F13+F16+F19+F22 -> 0 | G25: =+G13+G16+G19+G22 -> 0 | H25: =+H13+H16+H19+H22 -> 0 | I25: =+I13+I16+I19+I22 -> 0 | J25: =+J13+J16+J19+J22 -> 0 | K25: =+K13+K16+K19+K22 -> 0 | ... AQ25: =+AQ13+AQ16+AQ19+AQ22 -> 0
B26: Total OPEX ($m) | D26: =+D14+D17+D20+D23 -> 7.3225806 | E26: =+E14+E17+E20+E23 -> 7.4690323 | F26: =+F14+F17+F20+F23 -> 7.6184129 | G26: =+G14+G17+G20+G23 -> 7.7707812 | H26: =+H14+H17+H20+H23 -> 7.9261968 | I26: =+I14+I17+I20+I23 -> 8.0847207 | J26: =+J14+J17+J20+J23 -> 8.2464151 | K26: =+K14+K17+K20+K23 -> 8.4113434 | ... AQ26: =+AQ14+AQ17+AQ20+AQ23 -> 0
B28: EU ETS cost ($m) | D28: =IF(AND(1<=Cargo!$D$15,Regulation!$D$6="Yes"),Vessel!$D$7*Fuel!$E$15*Fuel!$E$12*(IF(D8<2024,0,IF(D8<2025,0.4,IF(D8<2026,0.7,1))))*Regulation!$D$9*Regulation!$D$7*Regulation!$D$8/1000000,0) -> 0.022296774 | E28: =IF(AND(2<=Cargo!$D$15,Regulation!$D$6="Yes"),Vessel!$D$7*Fuel!$E$15*Fuel!$E$12*(IF(E8<2024,0,IF(E8<2025,0.4,IF(E8<2026,0.7,1))))*Regulation!$D$9*Regulation!$D$7*Regulation!$D$8/1000000,0) -> 0.022296774 | F28: =IF(AND(3<=Cargo!$D$15,Regulation!$D$6="Yes"),Vessel!$D$7*Fuel!$E$15*Fuel!$E$12*(IF(F8<2024,0,IF(F8<2025,0.4,IF(F8<2026,0.7,1))))*Regulation!$D$9*Regulation!$D$7*Regulation!$D$8/1000000,0) -> 0.022296774 | G28: =IF(AND(4<=Cargo!$D$15,Regulation!$D$6="Yes"),Vessel!$D$7*Fuel!$E$15*Fuel!$E$12*(IF(G8<2024,0,IF(G8<2025,0.4,IF(G8<2026,0.7,1))))*Regulation!$D$9*Regulation!$D$7*Regulation!$D$8/1000000,0) -> 0.022296774 | H28: =IF(AND(5<=Cargo!$D$15,Regulation!$D$6="Yes"),Vessel!$D$7*Fuel!$E$15*Fuel!$E$12*(IF(H8<2024,0,IF(H8<2025,0.4,IF(H8<2026,0.7,1))))*Regulation!$D$9*Regulation!$D$7*Regulation!$D$8/1000000,0) -> 0.022296774 | I28: =IF(AND(6<=Cargo!$D$15,Regulation!$D$6="Yes"),Vessel!$D$7*Fuel!$E$15*Fuel!$E$12*(IF(I8<2024,0,IF(I8<2025,0.4,IF(I8<2026,0.7,1))))*Regulation!$D$9*Regulation!$D$7*Regulation!$D$8/1000000,0) -> 0.022296774 | J28: =IF(AND(7<=Cargo!$D$15,Regulation!$D$6="Yes"),Vessel!$D$7*Fuel!$E$15*Fuel!$E$12*(IF(J8<2024,0,IF(J8<2025,0.4,IF(J8<2026,0.7,1))))*Regulation!$D$9*Regulation!$D$7*Regulation!$D$8/1000000,0) -> 0.022296774 | K28: =IF(AND(8<=Cargo!$D$15,Regulation!$D$6="Yes"),Vessel!$D$7*Fuel!$E$15*Fuel!$E$12*(IF(K8<2024,0,IF(K8<2025,0.4,IF(K8<2026,0.7,1))))*Regulation!$D$9*Regulation!$D$7*Regulation!$D$8/1000000,0) -> 0.022296774 | L28: =IF(AND(9<=Cargo!$D$15,Regulation!$D$6="Yes"),Vessel!$D$7*Fuel!$E$15*Fuel!$E$12*(IF(L8<2024,0,IF(L8<2025,0.4,IF(L8<2026,0.7,1))))*Regulation!$D$9*Regulation!$D$7*Regulation!$D$8/1000000,0) -> 0.022296774 | M28: =IF(AND(10<=Cargo!$D$15,Regulation!$D$6="Yes"),Vessel!$D$7*Fuel!$E$15*Fuel!$E$12*(IF(M8<2024,0,IF(M8<2025,0.4,IF(M8<2026,0.7,1))))*Regulation!$D$9*Regulation!$D$7*Regulation!$D$8/1000000,0) -> 0.022296774 | N28: =IF(AND(11<=Cargo!$D$15,Regulation!$D$6="Yes"),Vessel!$D$7*Fuel!$E$15*Fuel!$E$12*(IF(N8<2024,0,IF(N8<2025,0.4,IF(N8<2026,0.7,1))))*Regulation!$D$9*Regulation!$D$7*Regulation!$D$8/1000000,0) -> 0.022296774 | O28: =IF(AND(12<=Cargo!$D$15,Regulation!$D$6="Yes"),Vessel!$D$7*Fuel!$E$15*Fuel!$E$12*(IF(O8<2024,0,IF(O8<2025,0.4,IF(O8<2026,0.7,1))))*Regulation!$D$9*Regulation!$D$7*Regulation!$D$8/1000000,0) -> 0.022296774 | P28: =IF(AND(13<=Cargo!$D$15,Regulation!$D$6="Yes"),Vessel!$D$7*Fuel!$E$15*Fuel!$E$12*(IF(P8<2024,0,IF(P8<2025,0.4,IF(P8<2026,0.7,1))))*Regulation!$D$9*Regulation!$D$7*Regulation!$D$8/1000000,0) -> 0.022296774 | Q28: =IF(AND(14<=Cargo!$D$15,Regulation!$D$6="Yes"),Vessel!$D$7*Fuel!$E$15*Fuel!$E$12*(IF(Q8<2024,0,IF(Q8<2025,0.4,IF(Q8<2026,0.7,1))))*Regulation!$D$9*Regulation!$D$7*Regulation!$D$8/1000000,0) -> 0.022296774 | R28: =IF(AND(15<=Cargo!$D$15,Regulation!$D$6="Yes"),Vessel!$D$7*Fuel!$E$15*Fuel!$E$12*(IF(R8<2024,0,IF(R8<2025,0.4,IF(R8<2026,0.7,1))))*Regulation!$D$9*Regulation!$D$7*Regulation!$D$8/1000000,0) -> 0.022296774 | S28: =IF(AND(16<=Cargo!$D$15,Regulation!$D$6="Yes"),Vessel!$D$7*Fuel!$E$15*Fuel!$E$12*(IF(S8<2024,0,IF(S8<2025,0.4,IF(S8<2026,0.7,1))))*Regulation!$D$9*Regulation!$D$7*Regulation!$D$8/1000000,0) -> 0.022296774 | T28: =IF(AND(17<=Cargo!$D$15,Regulation!$D$6="Yes"),Vessel!$D$7*Fuel!$E$15*Fuel!$E$12*(IF(T8<2024,0,IF(T8<2025,0.4,IF(T8<2026,0.7,1))))*Regulation!$D$9*Regulation!$D$7*Regulation!$D$8/1000000,0) -> 0.022296774 | U28: =IF(AND(18<=Cargo!$D$15,Regulation!$D$6="Yes"),Vessel!$D$7*Fuel!$E$15*Fuel!$E$12*(IF(U8<2024,0,IF(U8<2025,0.4,IF(U8<2026,0.7,1))))*Regulation!$D$9*Regulation!$D$7*Regulation!$D$8/1000000,0) -> 0.022296774 | V28: =IF(AND(19<=Cargo!$D$15,Regulation!$D$6="Yes"),Vessel!$D$7*Fuel!$E$15*Fuel!$E$12*(IF(V8<2024,0,IF(V8<2025,0.4,IF(V8<2026,0.7,1))))*Regulation!$D$9*Regulation!$D$7*Regulation!$D$8/1000000,0) -> 0.022296774 | W28: =IF(AND(20<=Cargo!$D$15,Regulation!$D$6="Yes"),Vessel!$D$7*Fuel!$E$15*Fuel!$E$12*(IF(W8<2024,0,IF(W8<2025,0.4,IF(W8<2026,0.7,1))))*Regulation!$D$9*Regulation!$D$7*Regulation!$D$8/1000000,0) -> 0.022296774 | X28: =IF(AND(21<=Cargo!$D$15,Regulation!$D$6="Yes"),Vessel!$D$7*Fuel!$E$15*Fuel!$E$12*(IF(X8<2024,0,IF(X8<2025,0.4,IF(X8<2026,0.7,1))))*Regulation!$D$9*Regulation!$D$7*Regulation!$D$8/1000000,0) -> 0 | Y28: =IF(AND(22<=Cargo!$D$15,Regulation!$D$6="Yes"),Vessel!$D$7*Fuel!$E$15*Fuel!$E$12*(IF(Y8<2024,0,IF(Y8<2025,0.4,IF(Y8<2026,0.7,1))))*Regulation!$D$9*Regulation!$D$7*Regulation!$D$8/1000000,0) -> 0 | Z28: =IF(AND(23<=Cargo!$D$15,Regulation!$D$6="Yes"),Vessel!$D$7*Fuel!$E$15*Fuel!$E$12*(IF(Z8<2024,0,IF(Z8<2025,0.4,IF(Z8<2026,0.7,1))))*Regulation!$D$9*Regulation!$D$7*Regulation!$D$8/1000000,0) -> 0 | AA28: =IF(AND(24<=Cargo!$D$15,Regulation!$D$6="Yes"),Vessel!$D$7*Fuel!$E$15*Fuel!$E$12*(IF(AA8<2024,0,IF(AA8<2025,0.4,IF(AA8<2026,0.7,1))))*Regulation!$D$9*Regulation!$D$7*Regulation!$D$8/1000000,0) -> 0 | AB28: =IF(AND(25<=Cargo!$D$15,Regulation!$D$6="Yes"),Vessel!$D$7*Fuel!$E$15*Fuel!$E$12*(IF(AB8<2024,0,IF(AB8<2025,0.4,IF(AB8<2026,0.7,1))))*Regulation!$D$9*Regulation!$D$7*Regulation!$D$8/1000000,0) -> 0 | AC28: =IF(AND(26<=Cargo!$D$15,Regulation!$D$6="Yes"),Vessel!$D$7*Fuel!$E$15*Fuel!$E$12*(IF(AC8<2024,0,IF(AC8<2025,0.4,IF(AC8<2026,0.7,1))))*Regulation!$D$9*Regulation!$D$7*Regulation!$D$8/1000000,0) -> 0 | AD28: =IF(AND(27<=Cargo!$D$15,Regulation!$D$6="Yes"),Vessel!$D$7*Fuel!$E$15*Fuel!$E$12*(IF(AD8<2024,0,IF(AD8<2025,0.4,IF(AD8<2026,0.7,1))))*Regulation!$D$9*Regulation!$D$7*Regulation!$D$8/1000000,0) -> 0 | AE28: =IF(AND(28<=Cargo!$D$15,Regulation!$D$6="Yes"),Vessel!$D$7*Fuel!$E$15*Fuel!$E$12*(IF(AE8<2024,0,IF(AE8<2025,0.4,IF(AE8<2026,0.7,1))))*Regulation!$D$9*Regulation!$D$7*Regulation!$D$8/1000000,0) -> 0 | AF28: =IF(AND(29<=Cargo!$D$15,Regulation!$D$6="Yes"),Vessel!$D$7*Fuel!$E$15*Fuel!$E$12*(IF(AF8<2024,0,IF(AF8<2025,0.4,IF(AF8<2026,0.7,1))))*Regulation!$D$9*Regulation!$D$7*Regulation!$D$8/1000000,0) -> 0 | AG28: =IF(AND(30<=Cargo!$D$15,Regulation!$D$6="Yes"),Vessel!$D$7*Fuel!$E$15*Fuel!$E$12*(IF(AG8<2024,0,IF(AG8<2025,0.4,IF(AG8<2026,0.7,1))))*Regulation!$D$9*Regulation!$D$7*Regulation!$D$8/1000000,0) -> 0 | AH28: =IF(AND(31<=Cargo!$D$15,Regulation!$D$6="Yes"),Vessel!$D$7*Fuel!$E$15*Fuel!$E$12*(IF(AH8<2024,0,IF(AH8<2025,0.4,IF(AH8<2026,0.7,1))))*Regulation!$D$9*Regulation!$D$7*Regulation!$D$8/1000000,0) -> 0 | AI28: =IF(AND(32<=Cargo!$D$15,Regulation!$D$6="Yes"),Vessel!$D$7*Fuel!$E$15*Fuel!$E$12*(IF(AI8<2024,0,IF(AI8<2025,0.4,IF(AI8<2026,0.7,1))))*Regulation!$D$9*Regulation!$D$7*Regulation!$D$8/1000000,0) -> 0 | AJ28: =IF(AND(33<=Cargo!$D$15,Regulation!$D$6="Yes"),Vessel!$D$7*Fuel!$E$15*Fuel!$E$12*(IF(AJ8<2024,0,IF(AJ8<2025,0.4,IF(AJ8<2026,0.7,1))))*Regulation!$D$9*Regulation!$D$7*Regulation!$D$8/1000000,0) -> 0 | AK28: =IF(AND(34<=Cargo!$D$15,Regulation!$D$6="Yes"),Vessel!$D$7*Fuel!$E$15*Fuel!$E$12*(IF(AK8<2024,0,IF(AK8<2025,0.4,IF(AK8<2026,0.7,1))))*Regulation!$D$9*Regulation!$D$7*Regulation!$D$8/1000000,0) -> 0 | AL28: =IF(AND(35<=Cargo!$D$15,Regulation!$D$6="Yes"),Vessel!$D$7*Fuel!$E$15*Fuel!$E$12*(IF(AL8<2024,0,IF(AL8<2025,0.4,IF(AL8<2026,0.7,1))))*Regulation!$D$9*Regulation!$D$7*Regulation!$D$8/1000000,0) -> 0 | AM28: =IF(AND(36<=Cargo!$D$15,Regulation!$D$6="Yes"),Vessel!$D$7*Fuel!$E$15*Fuel!$E$12*(IF(AM8<2024,0,IF(AM8<2025,0.4,IF(AM8<2026,0.7,1))))*Regulation!$D$9*Regulation!$D$7*Regulation!$D$8/1000000,0) -> 0 | AN28: =IF(AND(37<=Cargo!$D$15,Regulation!$D$6="Yes"),Vessel!$D$7*Fuel!$E$15*Fuel!$E$12*(IF(AN8<2024,0,IF(AN8<2025,0.4,IF(AN8<2026,0.7,1))))*Regulation!$D$9*Regulation!$D$7*Regulation!$D$8/1000000,0) -> 0 | AO28: =IF(AND(38<=Cargo!$D$15,Regulation!$D$6="Yes"),Vessel!$D$7*Fuel!$E$15*Fuel!$E$12*(IF(AO8<2024,0,IF(AO8<2025,0.4,IF(AO8<2026,0.7,1))))*Regulation!$D$9*Regulation!$D$7*Regulation!$D$8/1000000,0) -> 0 | AP28: =IF(AND(39<=Cargo!$D$15,Regulation!$D$6="Yes"),Vessel!$D$7*Fuel!$E$15*Fuel!$E$12*(IF(AP8<2024,0,IF(AP8<2025,0.4,IF(AP8<2026,0.7,1))))*Regulation!$D$9*Regulation!$D$7*Regulation!$D$8/1000000,0) -> 0 | AQ28: =IF(AND(40<=Cargo!$D$15,Regulation!$D$6="Yes"),Vessel!$D$7*Fuel!$E$15*Fuel!$E$12*(IF(AQ8<2024,0,IF(AQ8<2025,0.4,IF(AQ8<2026,0.7,1))))*Regulation!$D$9*Regulation!$D$7*Regulation!$D$8/1000000,0) -> 0
B29: FuelEU Maritime cost ($m) | D29: =IF(AND(1<=Cargo!$D$15,Regulation!$D$14="Yes"),MAX(0,(Fuel!$E$14-Regulation!$D$17*(1-(IF(D8<2025,0,IF(D8<2030,0.02,IF(D8<2035,0.06,IF(D8<2040,0.145,IF(D8<2045,0.31,IF(D8<2050,0.62,0.8)))))))))*(Vessel!$D$7*Fuel!$E$15*Fuel!$E$13)/Fuel!$E$14/Regulation!$D$16*Regulation!$D$15*Regulation!$D$18*Regulation!$D$8/1000000),0) -> 0 | E29: =IF(AND(2<=Cargo!$D$15,Regulation!$D$14="Yes"),MAX(0,(Fuel!$E$14-Regulation!$D$17*(1-(IF(E8<2025,0,IF(E8<2030,0.02,IF(E8<2035,0.06,IF(E8<2040,0.145,IF(E8<2045,0.31,IF(E8<2050,0.62,0.8)))))))))*(Vessel!$D$7*Fuel!$E$15*Fuel!$E$13)/Fuel!$E$14/Regulation!$D$16*Regulation!$D$15*Regulation!$D$18*Regulation!$D$8/1000000),0) -> 0 | F29: =IF(AND(3<=Cargo!$D$15,Regulation!$D$14="Yes"),MAX(0,(Fuel!$E$14-Regulation!$D$17*(1-(IF(F8<2025,0,IF(F8<2030,0.02,IF(F8<2035,0.06,IF(F8<2040,0.145,IF(F8<2045,0.31,IF(F8<2050,0.62,0.8)))))))))*(Vessel!$D$7*Fuel!$E$15*Fuel!$E$13)/Fuel!$E$14/Regulation!$D$16*Regulation!$D$15*Regulation!$D$18*Regulation!$D$8/1000000),0) -> 0 | G29: =IF(AND(4<=Cargo!$D$15,Regulation!$D$14="Yes"),MAX(0,(Fuel!$E$14-Regulation!$D$17*(1-(IF(G8<2025,0,IF(G8<2030,0.02,IF(G8<2035,0.06,IF(G8<2040,0.145,IF(G8<2045,0.31,IF(G8<2050,0.62,0.8)))))))))*(Vessel!$D$7*Fuel!$E$15*Fuel!$E$13)/Fuel!$E$14/Regulation!$D$16*Regulation!$D$15*Regulation!$D$18*Regulation!$D$8/1000000),0) -> 0 | H29: =IF(AND(5<=Cargo!$D$15,Regulation!$D$14="Yes"),MAX(0,(Fuel!$E$14-Regulation!$D$17*(1-(IF(H8<2025,0,IF(H8<2030,0.02,IF(H8<2035,0.06,IF(H8<2040,0.145,IF(H8<2045,0.31,IF(H8<2050,0.62,0.8)))))))))*(Vessel!$D$7*Fuel!$E$15*Fuel!$E$13)/Fuel!$E$14/Regulation!$D$16*Regulation!$D$15*Regulation!$D$18*Regulation!$D$8/1000000),0) -> 0 | I29: =IF(AND(6<=Cargo!$D$15,Regulation!$D$14="Yes"),MAX(0,(Fuel!$E$14-Regulation!$D$17*(1-(IF(I8<2025,0,IF(I8<2030,0.02,IF(I8<2035,0.06,IF(I8<2040,0.145,IF(I8<2045,0.31,IF(I8<2050,0.62,0.8)))))))))*(Vessel!$D$7*Fuel!$E$15*Fuel!$E$13)/Fuel!$E$14/Regulation!$D$16*Regulation!$D$15*Regulation!$D$18*Regulation!$D$8/1000000),0) -> 0 | J29: =IF(AND(7<=Cargo!$D$15,Regulation!$D$14="Yes"),MAX(0,(Fuel!$E$14-Regulation!$D$17*(1-(IF(J8<2025,0,IF(J8<2030,0.02,IF(J8<2035,0.06,IF(J8<2040,0.145,IF(J8<2045,0.31,IF(J8<2050,0.62,0.8)))))))))*(Vessel!$D$7*Fuel!$E$15*Fuel!$E$13)/Fuel!$E$14/Regulation!$D$16*Regulation!$D$15*Regulation!$D$18*Regulation!$D$8/1000000),0) -> 0 | K29: =IF(AND(8<=Cargo!$D$15,Regulation!$D$14="Yes"),MAX(0,(Fuel!$E$14-Regulation!$D$17*(1-(IF(K8<2025,0,IF(K8<2030,0.02,IF(K8<2035,0.06,IF(K8<2040,0.145,IF(K8<2045,0.31,IF(K8<2050,0.62,0.8)))))))))*(Vessel!$D$7*Fuel!$E$15*Fuel!$E$13)/Fuel!$E$14/Regulation!$D$16*Regulation!$D$15*Regulation!$D$18*Regulation!$D$8/1000000),0) -> 0 | L29: =IF(AND(9<=Cargo!$D$15,Regulation!$D$14="Yes"),MAX(0,(Fuel!$E$14-Regulation!$D$17*(1-(IF(L8<2025,0,IF(L8<2030,0.02,IF(L8<2035,0.06,IF(L8<2040,0.145,IF(L8<2045,0.31,IF(L8<2050,0.62,0.8)))))))))*(Vessel!$D$7*Fuel!$E$15*Fuel!$E$13)/Fuel!$E$14/Regulation!$D$16*Regulation!$D$15*Regulation!$D$18*Regulation!$D$8/1000000),0) -> 0 | M29: =IF(AND(10<=Cargo!$D$15,Regulation!$D$14="Yes"),MAX(0,(Fuel!$E$14-Regulation!$D$17*(1-(IF(M8<2025,0,IF(M8<2030,0.02,IF(M8<2035,0.06,IF(M8<2040,0.145,IF(M8<2045,0.31,IF(M8<2050,0.62,0.8)))))))))*(Vessel!$D$7*Fuel!$E$15*Fuel!$E$13)/Fuel!$E$14/Regulation!$D$16*Regulation!$D$15*Regulation!$D$18*Regulation!$D$8/1000000),0) -> 0 | N29: =IF(AND(11<=Cargo!$D$15,Regulation!$D$14="Yes"),MAX(0,(Fuel!$E$14-Regulation!$D$17*(1-(IF(N8<2025,0,IF(N8<2030,0.02,IF(N8<2035,0.06,IF(N8<2040,0.145,IF(N8<2045,0.31,IF(N8<2050,0.62,0.8)))))))))*(Vessel!$D$7*Fuel!$E$15*Fuel!$E$13)/Fuel!$E$14/Regulation!$D$16*Regulation!$D$15*Regulation!$D$18*Regulation!$D$8/1000000),0) -> 0 | O29: =IF(AND(12<=Cargo!$D$15,Regulation!$D$14="Yes"),MAX(0,(Fuel!$E$14-Regulation!$D$17*(1-(IF(O8<2025,0,IF(O8<2030,0.02,IF(O8<2035,0.06,IF(O8<2040,0.145,IF(O8<2045,0.31,IF(O8<2050,0.62,0.8)))))))))*(Vessel!$D$7*Fuel!$E$15*Fuel!$E$13)/Fuel!$E$14/Regulation!$D$16*Regulation!$D$15*Regulation!$D$18*Regulation!$D$8/1000000),0) -> 0 | P29: =IF(AND(13<=Cargo!$D$15,Regulation!$D$14="Yes"),MAX(0,(Fuel!$E$14-Regulation!$D$17*(1-(IF(P8<2025,0,IF(P8<2030,0.02,IF(P8<2035,0.06,IF(P8<2040,0.145,IF(P8<2045,0.31,IF(P8<2050,0.62,0.8)))))))))*(Vessel!$D$7*Fuel!$E$15*Fuel!$E$13)/Fuel!$E$14/Regulation!$D$16*Regulation!$D$15*Regulation!$D$18*Regulation!$D$8/1000000),0) -> 0 | Q29: =IF(AND(14<=Cargo!$D$15,Regulation!$D$14="Yes"),MAX(0,(Fuel!$E$14-Regulation!$D$17*(1-(IF(Q8<2025,0,IF(Q8<2030,0.02,IF(Q8<2035,0.06,IF(Q8<2040,0.145,IF(Q8<2045,0.31,IF(Q8<2050,0.62,0.8)))))))))*(Vessel!$D$7*Fuel!$E$15*Fuel!$E$13)/Fuel!$E$14/Regulation!$D$16*Regulation!$D$15*Regulation!$D$18*Regulation!$D$8/1000000),0) -> 0 | R29: =IF(AND(15<=Cargo!$D$15,Regulation!$D$14="Yes"),MAX(0,(Fuel!$E$14-Regulation!$D$17*(1-(IF(R8<2025,0,IF(R8<2030,0.02,IF(R8<2035,0.06,IF(R8<2040,0.145,IF(R8<2045,0.31,IF(R8<2050,0.62,0.8)))))))))*(Vessel!$D$7*Fuel!$E$15*Fuel!$E$13)/Fuel!$E$14/Regulation!$D$16*Regulation!$D$15*Regulation!$D$18*Regulation!$D$8/1000000),0) -> 0 | S29: =IF(AND(16<=Cargo!$D$15,Regulation!$D$14="Yes"),MAX(0,(Fuel!$E$14-Regulation!$D$17*(1-(IF(S8<2025,0,IF(S8<2030,0.02,IF(S8<2035,0.06,IF(S8<2040,0.145,IF(S8<2045,0.31,IF(S8<2050,0.62,0.8)))))))))*(Vessel!$D$7*Fuel!$E$15*Fuel!$E$13)/Fuel!$E$14/Regulation!$D$16*Regulation!$D$15*Regulation!$D$18*Regulation!$D$8/1000000),0) -> 0 | T29: =IF(AND(17<=Cargo!$D$15,Regulation!$D$14="Yes"),MAX(0,(Fuel!$E$14-Regulation!$D$17*(1-(IF(T8<2025,0,IF(T8<2030,0.02,IF(T8<2035,0.06,IF(T8<2040,0.145,IF(T8<2045,0.31,IF(T8<2050,0.62,0.8)))))))))*(Vessel!$D$7*Fuel!$E$15*Fuel!$E$13)/Fuel!$E$14/Regulation!$D$16*Regulation!$D$15*Regulation!$D$18*Regulation!$D$8/1000000),0) -> 0 | U29: =IF(AND(18<=Cargo!$D$15,Regulation!$D$14="Yes"),MAX(0,(Fuel!$E$14-Regulation!$D$17*(1-(IF(U8<2025,0,IF(U8<2030,0.02,IF(U8<2035,0.06,IF(U8<2040,0.145,IF(U8<2045,0.31,IF(U8<2050,0.62,0.8)))))))))*(Vessel!$D$7*Fuel!$E$15*Fuel!$E$13)/Fuel!$E$14/Regulation!$D$16*Regulation!$D$15*Regulation!$D$18*Regulation!$D$8/1000000),0) -> 0 | V29: =IF(AND(19<=Cargo!$D$15,Regulation!$D$14="Yes"),MAX(0,(Fuel!$E$14-Regulation!$D$17*(1-(IF(V8<2025,0,IF(V8<2030,0.02,IF(V8<2035,0.06,IF(V8<2040,0.145,IF(V8<2045,0.31,IF(V8<2050,0.62,0.8)))))))))*(Vessel!$D$7*Fuel!$E$15*Fuel!$E$13)/Fuel!$E$14/Regulation!$D$16*Regulation!$D$15*Regulation!$D$18*Regulation!$D$8/1000000),0) -> 0 | W29: =IF(AND(20<=Cargo!$D$15,Regulation!$D$14="Yes"),MAX(0,(Fuel!$E$14-Regulation!$D$17*(1-(IF(W8<2025,0,IF(W8<2030,0.02,IF(W8<2035,0.06,IF(W8<2040,0.145,IF(W8<2045,0.31,IF(W8<2050,0.62,0.8)))))))))*(Vessel!$D$7*Fuel!$E$15*Fuel!$E$13)/Fuel!$E$14/Regulation!$D$16*Regulation!$D$15*Regulation!$D$18*Regulation!$D$8/1000000),0) -> 0 | X29: =IF(AND(21<=Cargo!$D$15,Regulation!$D$14="Yes"),MAX(0,(Fuel!$E$14-Regulation!$D$17*(1-(IF(X8<2025,0,IF(X8<2030,0.02,IF(X8<2035,0.06,IF(X8<2040,0.145,IF(X8<2045,0.31,IF(X8<2050,0.62,0.8)))))))))*(Vessel!$D$7*Fuel!$E$15*Fuel!$E$13)/Fuel!$E$14/Regulation!$D$16*Regulation!$D$15*Regulation!$D$18*Regulation!$D$8/1000000),0) -> 0 | Y29: =IF(AND(22<=Cargo!$D$15,Regulation!$D$14="Yes"),MAX(0,(Fuel!$E$14-Regulation!$D$17*(1-(IF(Y8<2025,0,IF(Y8<2030,0.02,IF(Y8<2035,0.06,IF(Y8<2040,0.145,IF(Y8<2045,0.31,IF(Y8<2050,0.62,0.8)))))))))*(Vessel!$D$7*Fuel!$E$15*Fuel!$E$13)/Fuel!$E$14/Regulation!$D$16*Regulation!$D$15*Regulation!$D$18*Regulation!$D$8/1000000),0) -> 0 | Z29: =IF(AND(23<=Cargo!$D$15,Regulation!$D$14="Yes"),MAX(0,(Fuel!$E$14-Regulation!$D$17*(1-(IF(Z8<2025,0,IF(Z8<2030,0.02,IF(Z8<2035,0.06,IF(Z8<2040,0.145,IF(Z8<2045,0.31,IF(Z8<2050,0.62,0.8)))))))))*(Vessel!$D$7*Fuel!$E$15*Fuel!$E$13)/Fuel!$E$14/Regulation!$D$16*Regulation!$D$15*Regulation!$D$18*Regulation!$D$8/1000000),0) -> 0 | AA29: =IF(AND(24<=Cargo!$D$15,Regulation!$D$14="Yes"),MAX(0,(Fuel!$E$14-Regulation!$D$17*(1-(IF(AA8<2025,0,IF(AA8<2030,0.02,IF(AA8<2035,0.06,IF(AA8<2040,0.145,IF(AA8<2045,0.31,IF(AA8<2050,0.62,0.8)))))))))*(Vessel!$D$7*Fuel!$E$15*Fuel!$E$13)/Fuel!$E$14/Regulation!$D$16*Regulation!$D$15*Regulation!$D$18*Regulation!$D$8/1000000),0) -> 0 | AB29: =IF(AND(25<=Cargo!$D$15,Regulation!$D$14="Yes"),MAX(0,(Fuel!$E$14-Regulation!$D$17*(1-(IF(AB8<2025,0,IF(AB8<2030,0.02,IF(AB8<2035,0.06,IF(AB8<2040,0.145,IF(AB8<2045,0.31,IF(AB8<2050,0.62,0.8)))))))))*(Vessel!$D$7*Fuel!$E$15*Fuel!$E$13)/Fuel!$E$14/Regulation!$D$16*Regulation!$D$15*Regulation!$D$18*Regulation!$D$8/1000000),0) -> 0 | AC29: =IF(AND(26<=Cargo!$D$15,Regulation!$D$14="Yes"),MAX(0,(Fuel!$E$14-Regulation!$D$17*(1-(IF(AC8<2025,0,IF(AC8<2030,0.02,IF(AC8<2035,0.06,IF(AC8<2040,0.145,IF(AC8<2045,0.31,IF(AC8<2050,0.62,0.8)))))))))*(Vessel!$D$7*Fuel!$E$15*Fuel!$E$13)/Fuel!$E$14/Regulation!$D$16*Regulation!$D$15*Regulation!$D$18*Regulation!$D$8/1000000),0) -> 0 | AD29: =IF(AND(27<=Cargo!$D$15,Regulation!$D$14="Yes"),MAX(0,(Fuel!$E$14-Regulation!$D$17*(1-(IF(AD8<2025,0,IF(AD8<2030,0.02,IF(AD8<2035,0.06,IF(AD8<2040,0.145,IF(AD8<2045,0.31,IF(AD8<2050,0.62,0.8)))))))))*(Vessel!$D$7*Fuel!$E$15*Fuel!$E$13)/Fuel!$E$14/Regulation!$D$16*Regulation!$D$15*Regulation!$D$18*Regulation!$D$8/1000000),0) -> 0 | AE29: =IF(AND(28<=Cargo!$D$15,Regulation!$D$14="Yes"),MAX(0,(Fuel!$E$14-Regulation!$D$17*(1-(IF(AE8<2025,0,IF(AE8<2030,0.02,IF(AE8<2035,0.06,IF(AE8<2040,0.145,IF(AE8<2045,0.31,IF(AE8<2050,0.62,0.8)))))))))*(Vessel!$D$7*Fuel!$E$15*Fuel!$E$13)/Fuel!$E$14/Regulation!$D$16*Regulation!$D$15*Regulation!$D$18*Regulation!$D$8/1000000),0) -> 0 | AF29: =IF(AND(29<=Cargo!$D$15,Regulation!$D$14="Yes"),MAX(0,(Fuel!$E$14-Regulation!$D$17*(1-(IF(AF8<2025,0,IF(AF8<2030,0.02,IF(AF8<2035,0.06,IF(AF8<2040,0.145,IF(AF8<2045,0.31,IF(AF8<2050,0.62,0.8)))))))))*(Vessel!$D$7*Fuel!$E$15*Fuel!$E$13)/Fuel!$E$14/Regulation!$D$16*Regulation!$D$15*Regulation!$D$18*Regulation!$D$8/1000000),0) -> 0 | AG29: =IF(AND(30<=Cargo!$D$15,Regulation!$D$14="Yes"),MAX(0,(Fuel!$E$14-Regulation!$D$17*(1-(IF(AG8<2025,0,IF(AG8<2030,0.02,IF(AG8<2035,0.06,IF(AG8<2040,0.145,IF(AG8<2045,0.31,IF(AG8<2050,0.62,0.8)))))))))*(Vessel!$D$7*Fuel!$E$15*Fuel!$E$13)/Fuel!$E$14/Regulation!$D$16*Regulation!$D$15*Regulation!$D$18*Regulation!$D$8/1000000),0) -> 0 | AH29: =IF(AND(31<=Cargo!$D$15,Regulation!$D$14="Yes"),MAX(0,(Fuel!$E$14-Regulation!$D$17*(1-(IF(AH8<2025,0,IF(AH8<2030,0.02,IF(AH8<2035,0.06,IF(AH8<2040,0.145,IF(AH8<2045,0.31,IF(AH8<2050,0.62,0.8)))))))))*(Vessel!$D$7*Fuel!$E$15*Fuel!$E$13)/Fuel!$E$14/Regulation!$D$16*Regulation!$D$15*Regulation!$D$18*Regulation!$D$8/1000000),0) -> 0 | AI29: =IF(AND(32<=Cargo!$D$15,Regulation!$D$14="Yes"),MAX(0,(Fuel!$E$14-Regulation!$D$17*(1-(IF(AI8<2025,0,IF(AI8<2030,0.02,IF(AI8<2035,0.06,IF(AI8<2040,0.145,IF(AI8<2045,0.31,IF(AI8<2050,0.62,0.8)))))))))*(Vessel!$D$7*Fuel!$E$15*Fuel!$E$13)/Fuel!$E$14/Regulation!$D$16*Regulation!$D$15*Regulation!$D$18*Regulation!$D$8/1000000),0) -> 0 | AJ29: =IF(AND(33<=Cargo!$D$15,Regulation!$D$14="Yes"),MAX(0,(Fuel!$E$14-Regulation!$D$17*(1-(IF(AJ8<2025,0,IF(AJ8<2030,0.02,IF(AJ8<2035,0.06,IF(AJ8<2040,0.145,IF(AJ8<2045,0.31,IF(AJ8<2050,0.62,0.8)))))))))*(Vessel!$D$7*Fuel!$E$15*Fuel!$E$13)/Fuel!$E$14/Regulation!$D$16*Regulation!$D$15*Regulation!$D$18*Regulation!$D$8/1000000),0) -> 0 | AK29: =IF(AND(34<=Cargo!$D$15,Regulation!$D$14="Yes"),MAX(0,(Fuel!$E$14-Regulation!$D$17*(1-(IF(AK8<2025,0,IF(AK8<2030,0.02,IF(AK8<2035,0.06,IF(AK8<2040,0.145,IF(AK8<2045,0.31,IF(AK8<2050,0.62,0.8)))))))))*(Vessel!$D$7*Fuel!$E$15*Fuel!$E$13)/Fuel!$E$14/Regulation!$D$16*Regulation!$D$15*Regulation!$D$18*Regulation!$D$8/1000000),0) -> 0 | AL29: =IF(AND(35<=Cargo!$D$15,Regulation!$D$14="Yes"),MAX(0,(Fuel!$E$14-Regulation!$D$17*(1-(IF(AL8<2025,0,IF(AL8<2030,0.02,IF(AL8<2035,0.06,IF(AL8<2040,0.145,IF(AL8<2045,0.31,IF(AL8<2050,0.62,0.8)))))))))*(Vessel!$D$7*Fuel!$E$15*Fuel!$E$13)/Fuel!$E$14/Regulation!$D$16*Regulation!$D$15*Regulation!$D$18*Regulation!$D$8/1000000),0) -> 0 | AM29: =IF(AND(36<=Cargo!$D$15,Regulation!$D$14="Yes"),MAX(0,(Fuel!$E$14-Regulation!$D$17*(1-(IF(AM8<2025,0,IF(AM8<2030,0.02,IF(AM8<2035,0.06,IF(AM8<2040,0.145,IF(AM8<2045,0.31,IF(AM8<2050,0.62,0.8)))))))))*(Vessel!$D$7*Fuel!$E$15*Fuel!$E$13)/Fuel!$E$14/Regulation!$D$16*Regulation!$D$15*Regulation!$D$18*Regulation!$D$8/1000000),0) -> 0 | AN29: =IF(AND(37<=Cargo!$D$15,Regulation!$D$14="Yes"),MAX(0,(Fuel!$E$14-Regulation!$D$17*(1-(IF(AN8<2025,0,IF(AN8<2030,0.02,IF(AN8<2035,0.06,IF(AN8<2040,0.145,IF(AN8<2045,0.31,IF(AN8<2050,0.62,0.8)))))))))*(Vessel!$D$7*Fuel!$E$15*Fuel!$E$13)/Fuel!$E$14/Regulation!$D$16*Regulation!$D$15*Regulation!$D$18*Regulation!$D$8/1000000),0) -> 0 | AO29: =IF(AND(38<=Cargo!$D$15,Regulation!$D$14="Yes"),MAX(0,(Fuel!$E$14-Regulation!$D$17*(1-(IF(AO8<2025,0,IF(AO8<2030,0.02,IF(AO8<2035,0.06,IF(AO8<2040,0.145,IF(AO8<2045,0.31,IF(AO8<2050,0.62,0.8)))))))))*(Vessel!$D$7*Fuel!$E$15*Fuel!$E$13)/Fuel!$E$14/Regulation!$D$16*Regulation!$D$15*Regulation!$D$18*Regulation!$D$8/1000000),0) -> 0 | AP29: =IF(AND(39<=Cargo!$D$15,Regulation!$D$14="Yes"),MAX(0,(Fuel!$E$14-Regulation!$D$17*(1-(IF(AP8<2025,0,IF(AP8<2030,0.02,IF(AP8<2035,0.06,IF(AP8<2040,0.145,IF(AP8<2045,0.31,IF(AP8<2050,0.62,0.8)))))))))*(Vessel!$D$7*Fuel!$E$15*Fuel!$E$13)/Fuel!$E$14/Regulation!$D$16*Regulation!$D$15*Regulation!$D$18*Regulation!$D$8/1000000),0) -> 0 | AQ29: =IF(AND(40<=Cargo!$D$15,Regulation!$D$14="Yes"),MAX(0,(Fuel!$E$14-Regulation!$D$17*(1-(IF(AQ8<2025,0,IF(AQ8<2030,0.02,IF(AQ8<2035,0.06,IF(AQ8<2040,0.145,IF(AQ8<2045,0.31,IF(AQ8<2050,0.62,0.8)))))))))*(Vessel!$D$7*Fuel!$E$15*Fuel!$E$13)/Fuel!$E$14/Regulation!$D$16*Regulation!$D$15*Regulation!$D$18*Regulation!$D$8/1000000),0) -> 0
